Workbook

Sheet RELATÓRIO APROV. DE LEGÍVEIS
C1: MEDIÇÃO DE SERVIÇOS
C2: Pregão Eletrônico Nº 90007/2024 - Processo nº 23.13.000003872-9
C3: OBRA: Contratação de empresa para para fornecimento de equipamentos novos e sem uso e de sistemas voltados à segurança global das vias sob circunscrição da Secretaria Municipal de Mobilidade | U3: Consórcio Anhanguera Segurança | AX3: CONTRATO NÚMERO: 018/2024
U4: Rua Itu, S/N, QD 03 LT 1-E, Sl 1001/1002, Torre 2, Edif. B E B Business, Vl Brasília | AD4: MÊS DE REFERÊNCIA: Abril de 2025 | AX4: DATA DA ASSINATURA: 19/12/2024
C5: LOCAL: Diversas vias do Município de Goiânia | U5: Aparecida de Goiânia - CEP 74.911-810 | AD5: NÚMERO DA MEDIÇÃO: 002 | AX5: PROCESSO SEI MÃE: 23.13.000003872-9
C6: PRAZO DE EXECUÇÃO DOS SERVIÇOS: 60 Meses | U6: CNPJ: 58.516.417/0001-91 | AD6: CONTRATADA: CONSÓRCIO ANHANGUERA SEGURANÇA | AX6: PROCESSO SEI: 24.13.000008566-8
C7: DATA DA ORDEM DE SERVIÇO: 19/12/2024 | U7: E-MAIL: comercial@laborengenharia.com
J10: IMAGEM REPETIDA (EM DUPLICIDADE) | K10: DIVERGÊNCIA IMAGEM (PAN / ZOOM) | L10: FALTA DE LUMINOSIDADE (IMAGEM ESCURA) | M10: FORA DE FOCO | N10: IMAGEM SEM PANORÂMICA/ZOOM | O10: PLACA REFLETIVA | P10: PROBLEMAS TÉCNICOS | Q10: VEÍCULO FORA DE ENQUADRAMENTO (CAMERA DESALINHADA) | R10: EXCESSO DE LUMINOSIDADE | S10: FORA DO PRAZO | T10: IMAGEM SEM VEÍCULO | AF10: DATA DE AFERICÃO INVÁLIDA/SEM VERIFICAÇÃO | AG10: DIVERGÊNCIA DE CADASTRO | AH10: EQUIPAMENTO EM TESTE | AI10: ERRO NA TARJA (CONFIGURAÇÕES) | AJ10: IMAGEM DE TESTE | AK10: IMAGEM ENCOBERTA (VEGETAÇÃO) | AL10: INTERFERÊNCIA FÍSICA | AM10: MAIS DE UM VEÍCULO NA FAIXA | AN10: MOTO PERMITIDO PARA CIRCULAÇAO NA VIA | AO10: OUTROS | AP10: PEDESTRE OU VEICULO TRACÃO ANIMAL/HUMANA | AQ10: PLACA ENCOBERTA PROPOSITALMENTE (OBSTRUÇÃO INTENCIONAL) | AR10: PLACA ESTRANGEIRA | AS10: PLACA NAO VISUALIZADA | AT10: PLACA ILEGÍVEL | AU10: REFLEXO SOL NA PLACA | AV10: SEMAFORO COM DEFEITO | AW10: SINALIZAÇÃO INSUFICIENTE | AX10: SITUAÇÃO DE DÚVIDA | AY10: VEÍCULO DE EMERGÊNCIA | AZ10: VEÍCULO ENTRE FAIXAS | BA10: VEÍCULO NAO CADASTRADO (SEM CADASTRO) | BB10: VEÍCULO OFICIAL AUTORIZADO | BC10: VEÍCULO SEM PLACA | BD10: VEICULO/MOTO NÃO É INFRATOR
B11: ENDEREÇO | C11: Faixa | D11: ITEM | E11: Equip | F11: Fluxo | G11: Dias Func. | H11: Registros | I11: Ilegíveis | J11: Erro Técnico | U11: Legíveis | V11: % Medido | W11: % Perda | X11: Válidas | Y11: 56732 | Z11: 60503 | AA11: 74550 | AB11: 74630 | AC11: 74710 | AD11: 75870 | AE11: Inválidas | AF11: Invalidação na Análise | BE11: T.Erro
A12: 1 | B12: Av. Independência, S/N, Qd. 61, Lt 9 B, Oeste/Leste | C12: GYN1R041-1 | D12: =VLOOKUP(C12,Planilha1!$J$2:$L$206,3,) -> 1 | E12: GYN1R041 | F12: 93556 | G12: 19 | H12: =I12+U12 -> 202 | I12: =SUM(J12:T12) -> 16 | L12: 2 | M12: 1 | S12: 13 | U12: =X12+AE12 -> 186 | V12: =IF(H12,U12/H12,0) -> 0.92079208 | W12: =IF(H12,I12/H12,0) -> 0.079207921 | X12: =SUM(Y12:AD12) -> 133 | AA12: 107 | AB12: 23 | AC12: 3 | AE12: =SUM(AF12:BD12) -> 53 | AL12: 1 | AM12: 6 | AQ12: 14 | AT12: 11 | AY12: 12 | BA12: 5 | BC12: 4 | BE12: =I12+AE12 -> 69
A13: 2 | B13: Av. Independência, S/N, Qd. 61, Lt 9 B, Oeste/Leste | C13: GYN1R041-2 | D13: =VLOOKUP(C13,Planilha1!$J$2:$L$206,3,) -> 1 | E13: GYN1R041 | F13: 108606 | G13: 19 | H13: =I13+U13 -> 167 | I13: =SUM(J13:T13) -> 20 | L13: 9 | S13: 11 | U13: =X13+AE13 -> 147 | V13: =IF(H13,U13/H13,0) -> 0.88023952 | W13: =IF(H13,I13/H13,0) -> 0.11976048 | X13: =SUM(Y13:AD13) -> 103 | AA13: 77 | AB13: 22 | AC13: 4 | AE13: =SUM(AF13:BD13) -> 44 | AL13: 1 | AM13: 12 | AQ13: 5 | AT13: 13 | AY13: 6 | BA13: 4 | BC13: 3 | BE13: =I13+AE13 -> 64
A14: 3 | B14: Av. Independência, 0, Qd. 94, Lt 1 B, Leste/Oeste | C14: GYN1R042-1 | D14: =VLOOKUP(C14,Planilha1!$J$2:$L$206,3,) -> 1 | E14: GYN1R042 | F14: 59738 | G14: 14 | H14: =I14+U14 -> 133 | I14: =SUM(J14:T14) -> 9 | Q14: 1 | S14: 8 | U14: =X14+AE14 -> 124 | V14: =IF(H14,U14/H14,0) -> 0.93233083 | W14: =IF(H14,I14/H14,0) -> 0.067669173 | X14: =SUM(Y14:AD14) -> 87 | AA14: 82 | AB14: 5 | AE14: =SUM(AF14:BD14) -> 37 | AJ14: 1 | AL14: 1 | AM14: 2 | AQ14: 10 | AT14: 3 | AY14: 8 | BA14: 6 | BC14: 6 | BE14: =I14+AE14 -> 46
A15: 4 | B15: Av. Independência, 0, Qd. 94, Lt 1 B, Leste/Oeste | C15: GYN1R042-2 | D15: =VLOOKUP(C15,Planilha1!$J$2:$L$206,3,) -> 1 | E15: GYN1R042 | F15: 112111 | G15: 14 | H15: =I15+U15 -> 92 | I15: =SUM(J15:T15) -> 4 | L15: 1 | R15: 1 | S15: 2 | U15: =X15+AE15 -> 88 | V15: =IF(H15,U15/H15,0) -> 0.95652174 | W15: =IF(H15,I15/H15,0) -> 0.043478261 | X15: =SUM(Y15:AD15) -> 61 | AA15: 55 | AB15: 5 | AC15: 1 | AE15: =SUM(AF15:BD15) -> 27 | AJ15: 1 | AM15: 1 | AQ15: 12 | AY15: 6 | BA15: 3 | BC15: 4 | BE15: =I15+AE15 -> 31
A16: 5 | B16: Av. Independência, 0, Qd. 103, Lt. 01, Leste/Oeste | C16: GYN1R043-1 | D16: =VLOOKUP(C16,Planilha1!$J$2:$L$206,3,) -> 1 | E16: GYN1R043 | F16: 10708 | G16: 2 | H16: =I16+U16 -> 45 | I16: =SUM(J16:T16) -> 3 | P16: 3 | U16: =X16+AE16 -> 42 | V16: =IF(H16,U16/H16,0) -> 0.93333333 | W16: =IF(H16,I16/H16,0) -> 0.066666667 | X16: =SUM(Y16:AD16) -> 11 | AA16: 9 | AB16: 2 | AE16: =SUM(AF16:BD16) -> 31 | AJ16: 17 | AQ16: 7 | AY16: 4 | BA16: 3 | BE16: =I16+AE16 -> 34
A17: 6 | B17: Av. Independência, 0, Qd. 103, Lt. 01, Leste/Oeste | C17: GYN1R043-2 | D17: =VLOOKUP(C17,Planilha1!$J$2:$L$206,3,) -> 1 | E17: GYN1R043 | F17: 13034 | G17: 2 | H17: =I17+U17 -> 32 | I17: =SUM(J17:T17) -> 1 | P17: 1 | U17: =X17+AE17 -> 31 | V17: =IF(H17,U17/H17,0) -> 0.96875 | W17: =IF(H17,I17/H17,0) -> 0.03125 | X17: =SUM(Y17:AD17) -> 8 | AA17: 8 | AE17: =SUM(AF17:BD17) -> 23 | AJ17: 18 | AQ17: 3 | BC17: 1 | BD17: 1 | BE17: =I17+AE17 -> 24
A18: 7 | B18: Av. Independência, 0, Qd. 83, Lt. 23, Oeste/Leste | C18: GYN1R044-1 | D18: =VLOOKUP(C18,Planilha1!$J$2:$L$206,3,) -> 1 | E18: GYN1R044 | F18: 14361 | G18: 2 | H18: =I18+U18 -> 11 | I18: =SUM(J18:T18) -> 0 | U18: =X18+AE18 -> 11 | V18: =IF(H18,U18/H18,0) -> 1 | W18: =IF(H18,I18/H18,0) -> 0 | X18: =SUM(Y18:AD18) -> 0 | AE18: =SUM(AF18:BD18) -> 11 | AJ18: 6 | AQ18: 3 | AS18: 1 | AY18: 1 | BE18: =I18+AE18 -> 11
A19: 8 | B19: Av. Independência, 0, Qd. 83, Lt. 23, Oeste/Leste | C19: GYN1R044-2 | D19: =VLOOKUP(C19,Planilha1!$J$2:$L$206,3,) -> 1 | E19: GYN1R044 | F19: 16044 | G19: 2 | H19: =I19+U19 -> 10 | I19: =SUM(J19:T19) -> 0 | U19: =X19+AE19 -> 10 | V19: =IF(H19,U19/H19,0) -> 1 | W19: =IF(H19,I19/H19,0) -> 0 | X19: =SUM(Y19:AD19) -> 0 | AE19: =SUM(AF19:BD19) -> 10 | AJ19: 8 | AT19: 2 | BE19: =I19+AE19 -> 10
A20: 9 | B20: Av. Antônio Fidélis, 0, Qd. 67, Lt 31, Oeste/Leste | C20: GYN1R045-1 | D20: =VLOOKUP(C20,Planilha1!$J$2:$L$206,3,) -> 1 | E20: GYN1R045 | F20: 3629 | G20: 1 | H20: =I20+U20 -> 131 | I20: =SUM(J20:T20) -> 3 | L20: 2 | Q20: 1 | U20: =X20+AE20 -> 128 | V20: =IF(H20,U20/H20,0) -> 0.97709924 | W20: =IF(H20,I20/H20,0) -> 0.022900763 | X20: =SUM(Y20:AD20) -> 47 | AA20: 34 | AB20: 10 | AC20: 3 | AE20: =SUM(AF20:BD20) -> 81 | AH20: 18 | AJ20: 58 | AM20: 1 | AS20: 1 | AW20: 1 | AY20: 1 | BA20: 1 | BE20: =I20+AE20 -> 84
A21: 10 | B21: Av. Antônio Fidélis, 0, Qd. 67, Lt 31, Oeste/Leste | C21: GYN1R045-2 | D21: =VLOOKUP(C21,Planilha1!$J$2:$L$206,3,) -> 1 | E21: GYN1R045 | F21: 3771 | G21: 1 | H21: =I21+U21 -> 137 | I21: =SUM(J21:T21) -> 3 | L21: 1 | M21: 2 | U21: =X21+AE21 -> 134 | V21: =IF(H21,U21/H21,0) -> 0.97810219 | W21: =IF(H21,I21/H21,0) -> 0.02189781 | X21: =SUM(Y21:AD21) -> 56 | AA21: 41 | AB21: 14 | AC21: 1 | AE21: =SUM(AF21:BD21) -> 78 | AH21: 8 | AJ21: 59 | AT21: 1 | AY21: 2 | AZ21: 6 | BA21: 1 | BC21: 1 | BE21: =I21+AE21 -> 81
A22: 11 | B22: Av. Antônio Fidélis, 0, Qd 155 Lt 01E, Leste/Oeste | C22: GYN1R046-1 | D22: =VLOOKUP(C22,Planilha1!$J$2:$L$206,3,) -> 1 | E22: GYN1R046 | F22: 3920 | G22: 1 | H22: =I22+U22 -> 691 | I22: =SUM(J22:T22) -> 4 | M22: 1 | P22: 2 | S22: 1 | U22: =X22+AE22 -> 687 | V22: =IF(H22,U22/H22,0) -> 0.99421129 | W22: =IF(H22,I22/H22,0) -> 0.005788712 | X22: =SUM(Y22:AD22) -> 1 | AA22: 1 | AE22: =SUM(AF22:BD22) -> 686 | AJ22: 684 | AT22: 1 | AY22: 1 | BE22: =I22+AE22 -> 690
A23: 12 | B23: Av. Antônio Fidélis, 0, Qd 155 Lt 01E, Leste/Oeste | C23: GYN1R046-2 | D23: =VLOOKUP(C23,Planilha1!$J$2:$L$206,3,) -> 1 | E23: GYN1R046 | F23: 4049 | G23: 1 | H23: =I23+U23 -> 596 | I23: =SUM(J23:T23) -> 3 | P23: 1 | T23: 2 | U23: =X23+AE23 -> 593 | V23: =IF(H23,U23/H23,0) -> 0.99496644 | W23: =IF(H23,I23/H23,0) -> 0.005033557 | X23: =SUM(Y23:AD23) -> 3 | AA23: 3 | AE23: =SUM(AF23:BD23) -> 590 | AJ23: 583 | AM23: 3 | AY23: 3 | BC23: 1 | BE23: =I23+AE23 -> 593
A24: 13 | B24: Av. Padre Orlando Morais X Rua Manaus, S/N, Cond. Livre Buritis, Norte/Sul | C24: GYN1R048-1 | D24: =VLOOKUP(C24,Planilha1!$J$2:$L$206,3,) -> 1 | E24: GYN1R048 | F24: 2000 | G24: 1 | H24: =I24+U24 -> 16 | I24: =SUM(J24:T24) -> 0 | U24: =X24+AE24 -> 16 | V24: =IF(H24,U24/H24,0) -> 1 | W24: =IF(H24,I24/H24,0) -> 0 | X24: =SUM(Y24:AD24) -> 0 | AE24: =SUM(AF24:BD24) -> 16 | AJ24: 12 | AW24: 4 | BE24: =I24+AE24 -> 16
A25: 14 | B25: Av. Padre Orlando Morais X Rua Manaus, S/N, Cond. Livre Buritis, Norte/Sul | C25: GYN1R048-2 | D25: =VLOOKUP(C25,Planilha1!$J$2:$L$206,3,) -> 1 | E25: GYN1R048 | F25: 4660 | G25: 1 | H25: =I25+U25 -> 33 | I25: =SUM(J25:T25) -> 2 | P25: 1 | T25: 1 | U25: =X25+AE25 -> 31 | V25: =IF(H25,U25/H25,0) -> 0.93939394 | W25: =IF(H25,I25/H25,0) -> 0.060606061 | X25: =SUM(Y25:AD25) -> 0 | AE25: =SUM(AF25:BD25) -> 31 | AJ25: 15 | AW25: 16 | BE25: =I25+AE25 -> 33
A26: 15 | B26: Av. Pe. Orlando Morais X Rua Manaus, S/N, Cond. Livre Buritis, Sul/Norte | C26: GYN1R049-1 | D26: =VLOOKUP(C26,Planilha1!$J$2:$L$206,3,) -> 1 | E26: GYN1R049 | F26: 1100 | G26: 1 | H26: =I26+U26 -> 26 | I26: =SUM(J26:T26) -> 0 | U26: =X26+AE26 -> 26 | V26: =IF(H26,U26/H26,0) -> 1 | W26: =IF(H26,I26/H26,0) -> 0 | X26: =SUM(Y26:AD26) -> 0 | AE26: =SUM(AF26:BD26) -> 26 | AJ26: 1 | AW26: 25 | BE26: =I26+AE26 -> 26
A27: 16 | B27: Av. Pe. Orlando Morais X Rua Manaus, S/N, Cond. Livre Buritis, Sul/Norte | C27: GYN1R049-2 | D27: =VLOOKUP(C27,Planilha1!$J$2:$L$206,3,) -> 1 | E27: GYN1R049 | F27: 2916 | G27: 1 | H27: =I27+U27 -> 18 | I27: =SUM(J27:T27) -> 0 | U27: =X27+AE27 -> 18 | V27: =IF(H27,U27/H27,0) -> 1 | W27: =IF(H27,I27/H27,0) -> 0 | X27: =SUM(Y27:AD27) -> 0 | AE27: =SUM(AF27:BD27) -> 18 | AW27: 18 | BE27: =I27+AE27 -> 18
A28: 17 | B28: Av. Independência com Al. Luci Rassi de Oliveira, 0, 0, Leste/Oeste | C28: GYN1R052-1 | D28: =VLOOKUP(C28,Planilha1!$J$2:$L$206,3,) -> 1 | E28: GYN1R052 | F28: 8797 | G28: 2 | H28: =I28+U28 -> 400 | I28: =SUM(J28:T28) -> 0 | U28: =X28+AE28 -> 400 | V28: =IF(H28,U28/H28,0) -> 1 | W28: =IF(H28,I28/H28,0) -> 0 | X28: =SUM(Y28:AD28) -> 0 | AE28: =SUM(AF28:BD28) -> 400 | AH28: 2 | AQ28: 1 | AW28: 391 | AY28: 5 | BC28: 1 | BE28: =I28+AE28 -> 400
A29: 18 | B29: Av. Independência com Al. Luci Rassi de Oliveira, 0, 0, Leste/Oeste | C29: GYN1R052-2 | D29: =VLOOKUP(C29,Planilha1!$J$2:$L$206,3,) -> 1 | E29: GYN1R052 | F29: 11263 | G29: 2 | H29: =I29+U29 -> 253 | I29: =SUM(J29:T29) -> 1 | T29: 1 | U29: =X29+AE29 -> 252 | V29: =IF(H29,U29/H29,0) -> 0.99604743 | W29: =IF(H29,I29/H29,0) -> 0.0039525692 | X29: =SUM(Y29:AD29) -> 0 | AE29: =SUM(AF29:BD29) -> 252 | AH29: 1 | AQ29: 5 | AW29: 242 | AY29: 4 | BE29: =I29+AE29 -> 253
A30: 19 | B30: Av. Independência com Al. Luci Rassi de Oliveira , 0, 0, Oeste/Leste | C30: GYN1R053-1 | D30: =VLOOKUP(C30,Planilha1!$J$2:$L$206,3,) -> 1 | E30: GYN1R053 | F30: 12194 | G30: 2 | H30: =I30+U30 -> 1063 | I30: =SUM(J30:T30) -> 10 | L30: 1 | P30: 2 | T30: 7 | U30: =X30+AE30 -> 1053 | V30: =IF(H30,U30/H30,0) -> 0.99059266 | W30: =IF(H30,I30/H30,0) -> 0.0094073377 | X30: =SUM(Y30:AD30) -> 0 | AE30: =SUM(AF30:BD30) -> 1053 | AH30: 1 | AJ30: 621 | AM30: 1 | AO30: 1 | AQ30: 5 | AS30: 1 | AT30: 2 | AW30: 383 | AY30: 2 | AZ30: 35 | BC30: 1 | BE30: =I30+AE30 -> 1063
A31: 20 | B31: Av. Independência com Al. Luci Rassi de Oliveira , 0, 0, Oeste/Leste | C31: GYN1R053-2 | D31: =VLOOKUP(C31,Planilha1!$J$2:$L$206,3,) -> 1 | E31: GYN1R053 | F31: 13468 | G31: 2 | H31: =I31+U31 -> 531 | I31: =SUM(J31:T31) -> 3 | M31: 1 | P31: 2 | U31: =X31+AE31 -> 528 | V31: =IF(H31,U31/H31,0) -> 0.99435028 | W31: =IF(H31,I31/H31,0) -> 0.0056497175 | X31: =SUM(Y31:AD31) -> 0 | AE31: =SUM(AF31:BD31) -> 528 | AH31: 5 | AJ31: 302 | AL31: 2 | AO31: 3 | AQ31: 2 | AW31: 209 | AY31: 3 | BB31: 2 | BE31: =I31+AE31 -> 531
A32: 21 | B32: Av. Laguna, 0, Oposto Congregação Cristã do Brasil, Norte-Sul | C32: GYN2L031-1 | D32: =VLOOKUP(C32,Planilha1!$J$2:$L$206,3,) -> 2 | E32: GYN2L031 | F32: 43995 | G32: 21 | H32: =I32+U32 -> 192 | I32: =SUM(J32:T32) -> 16 | S32: 16 | U32: =X32+AE32 -> 176 | V32: =IF(H32,U32/H32,0) -> 0.91666667 | W32: =IF(H32,I32/H32,0) -> 0.083333333 | X32: =SUM(Y32:AD32) -> 122 | AA32: 105 | AB32: 14 | AC32: 3 | AE32: =SUM(AF32:BD32) -> 54 | AJ32: 10 | AM32: 1 | AQ32: 16 | AS32: 1 | AT32: 3 | AY32: 11 | BA32: 2 | BC32: 10 | BE32: =I32+AE32 -> 70
A33: 22 | B33: Av. Laguna, 0, Oposto Congregação Cristã do Brasil, Norte-Sul | C33: GYN2L031-2 | D33: =VLOOKUP(C33,Planilha1!$J$2:$L$206,3,) -> 2 | E33: GYN2L031 | F33: 71217 | G33: 21 | H33: =I33+U33 -> 353 | I33: =SUM(J33:T33) -> 36 | L33: 1 | M33: 1 | P33: 2 | R33: 1 | S33: 31 | U33: =X33+AE33 -> 317 | V33: =IF(H33,U33/H33,0) -> 0.898017 | W33: =IF(H33,I33/H33,0) -> 0.101983 | X33: =SUM(Y33:AD33) -> 222 | AA33: 172 | AB33: 39 | AC33: 11 | AE33: =SUM(AF33:BD33) -> 95 | AJ33: 4 | AM33: 10 | AQ33: 29 | AR33: 1 | AT33: 8 | AU33: 1 | AX33: 1 | AY33: 11 | AZ33: 6 | BA33: 4 | BC33: 20 | BE33: =I33+AE33 -> 131
A34: 23 | B34: Av. Laguna, 0, Em frente a Congregação Cristã do Brasil, Sul/Norte | C34: GYN2L032-1 | D34: =VLOOKUP(C34,Planilha1!$J$2:$L$206,3,) -> 2 | E34: GYN2L032 | F34: 46375 | G34: 20 | H34: =I34+U34 -> 274 | I34: =SUM(J34:T34) -> 17 | S34: 17 | U34: =X34+AE34 -> 257 | V34: =IF(H34,U34/H34,0) -> 0.9379562 | W34: =IF(H34,I34/H34,0) -> 0.062043796 | X34: =SUM(Y34:AD34) -> 215 | AA34: 184 | AB34: 31 | AE34: =SUM(AF34:BD34) -> 42 | AG34: 1 | AM34: 1 | AQ34: 8 | AT34: 3 | AY34: 5 | AZ34: 1 | BA34: 6 | BC34: 17 | BE34: =I34+AE34 -> 59
A35: 24 | B35: Av. Laguna, 0, Em frente a Congregação Cristã do Brasil, Sul/Norte | C35: GYN2L032-2 | D35: =VLOOKUP(C35,Planilha1!$J$2:$L$206,3,) -> 2 | E35: GYN2L032 | F35: 78826 | G35: 20 | H35: =I35+U35 -> 284 | I35: =SUM(J35:T35) -> 28 | M35: 1 | Q35: 1 | S35: 26 | U35: =X35+AE35 -> 256 | V35: =IF(H35,U35/H35,0) -> 0.90140845 | W35: =IF(H35,I35/H35,0) -> 0.098591549 | X35: =SUM(Y35:AD35) -> 204 | AA35: 186 | AB35: 16 | AC35: 2 | AE35: =SUM(AF35:BD35) -> 52 | AG35: 1 | AM35: 4 | AQ35: 11 | AS35: 1 | AT35: 2 | AY35: 7 | AZ35: 3 | BA35: 4 | BC35: 19 | BE35: =I35+AE35 -> 80
A36: 25 | B36: Av. Antônio Fidelis, S/N, Qd. 107, Lt. 9 B, Leste/Oeste | C36: GYN2L033-1 | D36: =VLOOKUP(C36,Planilha1!$J$2:$L$206,3,) -> 2 | E36: GYN2L033 | F36: 120542 | G36: 20 | H36: =I36+U36 -> 122 | I36: =SUM(J36:T36) -> 8 | S36: 8 | U36: =X36+AE36 -> 114 | V36: =IF(H36,U36/H36,0) -> 0.93442623 | W36: =IF(H36,I36/H36,0) -> 0.06557377 | X36: =SUM(Y36:AD36) -> 70 | AA36: 61 | AB36: 8 | AC36: 1 | AE36: =SUM(AF36:BD36) -> 44 | AG36: 1 | AJ36: 2 | AM36: 3 | AQ36: 13 | AT36: 3 | AY36: 12 | BA36: 3 | BC36: 7 | BE36: =I36+AE36 -> 52
A37: 26 | B37: Av. Antônio Fidelis, S/N, Qd. 107, Lt. 9 B, Leste/Oeste | C37: GYN2L033-2 | D37: =VLOOKUP(C37,Planilha1!$J$2:$L$206,3,) -> 2 | E37: GYN2L033 | F37: 154755 | G37: 20 | H37: =I37+U37 -> 105 | I37: =SUM(J37:T37) -> 34 | L37: 2 | P37: 4 | Q37: 13 | T37: 15 | U37: =X37+AE37 -> 71 | V37: =IF(H37,U37/H37,0) -> 0.67619048 | W37: =IF(H37,I37/H37,0) -> 0.32380952 | X37: =SUM(Y37:AD37) -> 39 | AA37: 31 | AB37: 5 | AC37: 3 | AE37: =SUM(AF37:BD37) -> 32 | AJ37: 2 | AQ37: 8 | AT37: 3 | AY37: 5 | AZ37: 9 | BA37: 1 | BC37: 4 | BE37: =I37+AE37 -> 66
A38: 27 | B38: Av. Antônio Fidelis, S/N, Qd. 82, Lt. 9 B, Oeste/Leste | C38: GYN2L034-1 | D38: =VLOOKUP(C38,Planilha1!$J$2:$L$206,3,) -> 2 | E38: GYN2L034 | F38: 135125 | G38: 20 | H38: =I38+U38 -> 78 | I38: =SUM(J38:T38) -> 3 | S38: 3 | U38: =X38+AE38 -> 75 | V38: =IF(H38,U38/H38,0) -> 0.96153846 | W38: =IF(H38,I38/H38,0) -> 0.038461538 | X38: =SUM(Y38:AD38) -> 33 | AA38: 26 | AB38: 6 | AC38: 1 | AE38: =SUM(AF38:BD38) -> 42 | AI38: 1 | AJ38: 1 | AM38: 2 | AQ38: 14 | AT38: 2 | AY38: 10 | BA38: 5 | BC38: 7 | BE38: =I38+AE38 -> 45
A39: 28 | B39: Av. Antônio Fidelis, S/N, Qd. 82, Lt. 9 B, Oeste/Leste | C39: GYN2L034-2 | D39: =VLOOKUP(C39,Planilha1!$J$2:$L$206,3,) -> 2 | E39: GYN2L034 | F39: 188632 | G39: 20 | H39: =I39+U39 -> 99 | I39: =SUM(J39:T39) -> 11 | L39: 1 | P39: 1 | Q39: 4 | S39: 2 | T39: 3 | U39: =X39+AE39 -> 88 | V39: =IF(H39,U39/H39,0) -> 0.88888889 | W39: =IF(H39,I39/H39,0) -> 0.11111111 | X39: =SUM(Y39:AD39) -> 34 | AA39: 29 | AB39: 5 | AE39: =SUM(AF39:BD39) -> 54 | AM39: 7 | AQ39: 11 | AT39: 2 | AY39: 10 | AZ39: 8 | BA39: 7 | BC39: 9 | BE39: =I39+AE39 -> 65
A40: 29 | B40: AV PROF ALFREDO DE CASTRO, 0, QD AREA LT 4 B, LESTE/OESTE | C40: GYN2L131-1 | D40: =VLOOKUP(C40,Planilha1!$J$2:$L$206,3,) -> 2 | E40: GYN2L131 | F40: 205870 | G40: 30 | H40: =I40+U40 -> 262 | I40: =SUM(J40:T40) -> 9 | O40: 2 | P40: 1 | Q40: 4 | R40: 2 | U40: =X40+AE40 -> 253 | V40: =IF(H40,U40/H40,0) -> 0.96564885 | W40: =IF(H40,I40/H40,0) -> 0.034351145 | X40: =SUM(Y40:AD40) -> 134 | AA40: 97 | AB40: 28 | AC40: 9 | AE40: =SUM(AF40:BD40) -> 119 | AM40: 1 | AN40: 1 | AQ40: 23 | AT40: 3 | AY40: 47 | AZ40: 5 | BA40: 20 | BB40: 1 | BC40: 18 | BE40: =I40+AE40 -> 128
A41: 30 | B41: AV PROF ALFREDO DE CASTRO, 0, QD AREA LT 4 B, LESTE/OESTE | C41: GYN2L131-2 | D41: =VLOOKUP(C41,Planilha1!$J$2:$L$206,3,) -> 2 | E41: GYN2L131 | F41: 69380 | G41: 30 | H41: =I41+U41 -> 80 | I41: =SUM(J41:T41) -> 4 | O41: 1 | Q41: 1 | T41: 2 | U41: =X41+AE41 -> 76 | V41: =IF(H41,U41/H41,0) -> 0.95 | W41: =IF(H41,I41/H41,0) -> 0.05 | X41: =SUM(Y41:AD41) -> 37 | AA41: 25 | AB41: 10 | AC41: 2 | AE41: =SUM(AF41:BD41) -> 39 | AQ41: 3 | AT41: 1 | AY41: 7 | AZ41: 2 | BC41: 26 | BE41: =I41+AE41 -> 43
A42: 31 | B42: Av. Hailé Pinheiro x R. Do Golfinho, 0, Qd 38 Lt 28, Oeste-Leste | C42: GYN7M001-1 | D42: =VLOOKUP(C42,Planilha1!$J$2:$L$206,3,) -> 3 | E42: GYN7M001 | F42: 60127 | G42: 21 | H42: =I42+U42 -> 714 | I42: =SUM(J42:T42) -> 87 | K42: 1 | M42: 1 | P42: 19 | Q42: 3 | S42: 60 | T42: 3 | U42: =X42+AE42 -> 627 | V42: =IF(H42,U42/H42,0) -> 0.87815126 | W42: =IF(H42,I42/H42,0) -> 0.12184874 | X42: =SUM(Y42:AD42) -> 533 | Z42: 55 | AA42: 414 | AB42: 62 | AC42: 2 | AE42: =SUM(AF42:BD42) -> 94 | AG42: 2 | AJ42: 2 | AK42: 23 | AL42: 2 | AM42: 8 | AP42: 4 | AQ42: 12 | AS42: 4 | AT42: 5 | AV42: 1 | AY42: 22 | AZ42: 1 | BA42: 3 | BC42: 5 | BE42: =I42+AE42 -> 181
...

Sheet ITEM 01
C1: ='RELATÓRIO APROV. DE LEGÍVEIS'!C1 -> MEDIÇÃO DE SERVIÇOS
C2: ='RELATÓRIO APROV. DE LEGÍVEIS'!C2 -> Pregão Eletrônico Nº 90007/2024 - Processo nº 23.13.000003872-9
C3: ='RELATÓRIO APROV. DE LEGÍVEIS'!C3 -> OBRA: Contratação de empresa para para fornecimento de equipamentos novos e sem uso e de sistemas voltados à segurança global das vias sob circunscrição da Secretaria Municipal de Mobilidade | U3: ='RELATÓRIO APROV. DE LEGÍVEIS'!U3 -> Consórcio Anhanguera Segurança | AX3: ='RELATÓRIO APROV. DE LEGÍVEIS'!AX3 -> CONTRATO NÚMERO: 018/2024
U4: ='RELATÓRIO APROV. DE LEGÍVEIS'!U4 -> Rua Itu, S/N, QD 03 LT 1-E, Sl 1001/1002, Torre 2, Edif. B E B Business, Vl Brasília | AD4: ='RELATÓRIO APROV. DE LEGÍVEIS'!AD4 -> MÊS DE REFERÊNCIA: Abril de 2025 | AX4: ='RELATÓRIO APROV. DE LEGÍVEIS'!AX4 -> DATA DA ASSINATURA: 19/12/2024
C5: ='RELATÓRIO APROV. DE LEGÍVEIS'!C5 -> LOCAL: Diversas vias do Município de Goiânia | U5: ='RELATÓRIO APROV. DE LEGÍVEIS'!U5 -> Aparecida de Goiânia - CEP 74.911-810 | AD5: ='RELATÓRIO APROV. DE LEGÍVEIS'!AD5 -> NÚMERO DA MEDIÇÃO: 002 | AX5: ='RELATÓRIO APROV. DE LEGÍVEIS'!AX5 -> PROCESSO SEI MÃE: 23.13.000003872-9
C6: ='RELATÓRIO APROV. DE LEGÍVEIS'!C6 -> PRAZO DE EXECUÇÃO DOS SERVIÇOS: 60 Meses | U6: ='RELATÓRIO APROV. DE LEGÍVEIS'!U6 -> CNPJ: 58.516.417/0001-91 | AD6: ='RELATÓRIO APROV. DE LEGÍVEIS'!AD6 -> CONTRATADA: CONSÓRCIO ANHANGUERA SEGURANÇA | AX6: ='RELATÓRIO APROV. DE LEGÍVEIS'!AX6 -> PROCESSO SEI: 24.13.000008566-8
C7: ='RELATÓRIO APROV. DE LEGÍVEIS'!C7 -> DATA DA ORDEM DE SERVIÇO: 19/12/2024 | U7: ='RELATÓRIO APROV. DE LEGÍVEIS'!U7 -> E-MAIL: comercial@laborengenharia.com
C10: ITEM 01 | J10: IMAGEM REPETIDA (EM DUPLICIDADE) | K10: DIVERGÊNCIA IMAGEM (PAN / ZOOM) | L10: FALTA DE LUMINOSIDADE (IMAGEM ESCURA) | M10: FORA DE FOCO | N10: IMAGEM SEM PANORÂMICA/ZOOM | O10: PLACA REFLETIVA | P10: PROBLEMAS TÉCNICOS | Q10: VEÍCULO FORA DE ENQUADRAMENTO (CAMERA DESALINHADA) | R10: EXCESSO DE LUMINOSIDADE | S10: FORA DO PRAZO | T10: IMAGEM SEM VEÍCULO | AF10: DATA DE AFERICÃO INVÁLIDA/SEM VERIFICAÇÃO | AG10: DIVERGÊNCIA DE CADASTRO | AH10: EQUIPAMENTO EM TESTE | AI10: ERRO NA TARJA (CONFIGURAÇÕES) | AJ10: IMAGEM DE TESTE | AK10: IMAGEM ENCOBERTA (VEGETAÇÃO) | AL10: INTERFERÊNCIA FÍSICA | AM10: MAIS DE UM VEÍCULO NA FAIXA | AN10: MOTO PERMITIDO PARA CIRCULAÇAO NA VIA | AO10: OUTROS | AP10: PEDESTRE OU VEICULO TRACÃO ANIMAL/HUMANA | AQ10: PLACA ENCOBERTA PROPOSITALMENTE (OBSTRUÇÃO INTENCIONAL) | AR10: PLACA ESTRANGEIRA | AS10: PLACA NAO VISUALIZADA | AT10: PLACA ILEGÍVEL | AU10: REFLEXO SOL NA PLACA | AV10: SEMAFORO COM DEFEITO | AW10: SINALIZAÇÃO INSUFICIENTE | AX10: SITUAÇÃO DE DÚVIDA | AY10: VEÍCULO DE EMERGÊNCIA | AZ10: VEÍCULO ENTRE FAIXAS | BA10: VEÍCULO NAO CADASTRADO (SEM CADASTRO) | BB10: VEÍCULO OFICIAL AUTORIZADO | BC10: VEÍCULO SEM PLACA | BD10: VEICULO/MOTO NÃO É INFRATOR
B11: ENDEREÇO | C11: Faixa | D11: ITEM | E11: Equip | F11: Fluxo | G11: Dias Func. | H11: Registros | I11: Ilegíveis | J11: Erro Técnico | U11: Legíveis | V11: % Medido | W11: % Perda | X11: Válidas | Y11: 56732 | Z11: 60503 | AA11: 74550 | AB11: 74630 | AC11: 74710 | AD11: 75870 | AE11: Inválidas | AF11: Invalidação na Análise | BE11: T.Erro
A12: 1 | B12: Av. Independência, S/N, Qd. 61, Lt 9 B, Oeste/Leste | C12: GYN1R041-1 | D12: =VLOOKUP(C12,Planilha1!$J$2:$L$206,3,) -> 1 | E12: GYN1R041 | F12: 93556 | G12: 19 | H12: =I12+U12 -> 202 | I12: =SUM(J12:T12) -> 16 | L12: 2 | M12: 1 | S12: 13 | U12: =X12+AE12 -> 186 | V12: =IF(H12,U12/H12,0) -> 0.92079208 | W12: =IF(H12,I12/H12,0) -> 0.079207921 | X12: =SUM(Y12:AD12) -> 133 | AA12: 107 | AB12: 23 | AC12: 3 | AE12: =SUM(AF12:BD12) -> 53 | AL12: 1 | AM12: 6 | AQ12: 14 | AT12: 11 | AY12: 12 | BA12: 5 | BC12: 4 | BE12: =I12+AE12 -> 69
A13: 2 | B13: Av. Independência, S/N, Qd. 61, Lt 9 B, Oeste/Leste | C13: GYN1R041-2 | D13: =VLOOKUP(C13,Planilha1!$J$2:$L$206,3,) -> 1 | E13: GYN1R041 | F13: 108606 | G13: 19 | H13: =I13+U13 -> 167 | I13: =SUM(J13:T13) -> 20 | L13: 9 | S13: 11 | U13: =X13+AE13 -> 147 | V13: =IF(H13,U13/H13,0) -> 0.88023952 | W13: =IF(H13,I13/H13,0) -> 0.11976048 | X13: =SUM(Y13:AD13) -> 103 | AA13: 77 | AB13: 22 | AC13: 4 | AE13: =SUM(AF13:BD13) -> 44 | AL13: 1 | AM13: 12 | AQ13: 5 | AT13: 13 | AY13: 6 | BA13: 4 | BC13: 3 | BE13: =I13+AE13 -> 64
A14: 3 | B14: Av. Independência, 0, Qd. 94, Lt 1 B, Leste/Oeste | C14: GYN1R042-1 | D14: =VLOOKUP(C14,Planilha1!$J$2:$L$206,3,) -> 1 | E14: GYN1R042 | F14: 59738 | G14: 14 | H14: =I14+U14 -> 133 | I14: =SUM(J14:T14) -> 9 | Q14: 1 | S14: 8 | U14: =X14+AE14 -> 124 | V14: =IF(H14,U14/H14,0) -> 0.93233083 | W14: =IF(H14,I14/H14,0) -> 0.067669173 | X14: =SUM(Y14:AD14) -> 87 | AA14: 82 | AB14: 5 | AE14: =SUM(AF14:BD14) -> 37 | AJ14: 1 | AL14: 1 | AM14: 2 | AQ14: 10 | AT14: 3 | AY14: 8 | BA14: 6 | BC14: 6 | BE14: =I14+AE14 -> 46
A15: 4 | B15: Av. Independência, 0, Qd. 94, Lt 1 B, Leste/Oeste | C15: GYN1R042-2 | D15: =VLOOKUP(C15,Planilha1!$J$2:$L$206,3,) -> 1 | E15: GYN1R042 | F15: 112111 | G15: 14 | H15: =I15+U15 -> 92 | I15: =SUM(J15:T15) -> 4 | L15: 1 | R15: 1 | S15: 2 | U15: =X15+AE15 -> 88 | V15: =IF(H15,U15/H15,0) -> 0.95652174 | W15: =IF(H15,I15/H15,0) -> 0.043478261 | X15: =SUM(Y15:AD15) -> 61 | AA15: 55 | AB15: 5 | AC15: 1 | AE15: =SUM(AF15:BD15) -> 27 | AJ15: 1 | AM15: 1 | AQ15: 12 | AY15: 6 | BA15: 3 | BC15: 4 | BE15: =I15+AE15 -> 31
A16: 5 | B16: Av. Independência, 0, Qd. 103, Lt. 01, Leste/Oeste | C16: GYN1R043-1 | D16: =VLOOKUP(C16,Planilha1!$J$2:$L$206,3,) -> 1 | E16: GYN1R043 | F16: 10708 | G16: 2 | H16: =I16+U16 -> 45 | I16: =SUM(J16:T16) -> 3 | P16: 3 | U16: =X16+AE16 -> 42 | V16: =IF(H16,U16/H16,0) -> 0.93333333 | W16: =IF(H16,I16/H16,0) -> 0.066666667 | X16: =SUM(Y16:AD16) -> 11 | AA16: 9 | AB16: 2 | AE16: =SUM(AF16:BD16) -> 31 | AJ16: 17 | AQ16: 7 | AY16: 4 | BA16: 3 | BE16: =I16+AE16 -> 34
A17: 6 | B17: Av. Independência, 0, Qd. 103, Lt. 01, Leste/Oeste | C17: GYN1R043-2 | D17: =VLOOKUP(C17,Planilha1!$J$2:$L$206,3,) -> 1 | E17: GYN1R043 | F17: 13034 | G17: 2 | H17: =I17+U17 -> 32 | I17: =SUM(J17:T17) -> 1 | P17: 1 | U17: =X17+AE17 -> 31 | V17: =IF(H17,U17/H17,0) -> 0.96875 | W17: =IF(H17,I17/H17,0) -> 0.03125 | X17: =SUM(Y17:AD17) -> 8 | AA17: 8 | AE17: =SUM(AF17:BD17) -> 23 | AJ17: 18 | AQ17: 3 | BC17: 1 | BD17: 1 | BE17: =I17+AE17 -> 24
A18: 7 | B18: Av. Independência, 0, Qd. 83, Lt. 23, Oeste/Leste | C18: GYN1R044-1 | D18: =VLOOKUP(C18,Planilha1!$J$2:$L$206,3,) -> 1 | E18: GYN1R044 | F18: 14361 | G18: 2 | H18: =I18+U18 -> 11 | I18: =SUM(J18:T18) -> 0 | U18: =X18+AE18 -> 11 | V18: =IF(H18,U18/H18,0) -> 1 | W18: =IF(H18,I18/H18,0) -> 0 | X18: =SUM(Y18:AD18) -> 0 | AE18: =SUM(AF18:BD18) -> 11 | AJ18: 6 | AQ18: 3 | AS18: 1 | AY18: 1 | BE18: =I18+AE18 -> 11
A19: 8 | B19: Av. Independência, 0, Qd. 83, Lt. 23, Oeste/Leste | C19: GYN1R044-2 | D19: =VLOOKUP(C19,Planilha1!$J$2:$L$206,3,) -> 1 | E19: GYN1R044 | F19: 16044 | G19: 2 | H19: =I19+U19 -> 10 | I19: =SUM(J19:T19) -> 0 | U19: =X19+AE19 -> 10 | V19: =IF(H19,U19/H19,0) -> 1 | W19: =IF(H19,I19/H19,0) -> 0 | X19: =SUM(Y19:AD19) -> 0 | AE19: =SUM(AF19:BD19) -> 10 | AJ19: 8 | AT19: 2 | BE19: =I19+AE19 -> 10
A20: 9 | B20: Av. Antônio Fidélis, 0, Qd. 67, Lt 31, Oeste/Leste | C20: GYN1R045-1 | D20: =VLOOKUP(C20,Planilha1!$J$2:$L$206,3,) -> 1 | E20: GYN1R045 | F20: 3629 | G20: 1 | H20: =I20+U20 -> 131 | I20: =SUM(J20:T20) -> 3 | L20: 2 | Q20: 1 | U20: =X20+AE20 -> 128 | V20: =IF(H20,U20/H20,0) -> 0.97709924 | W20: =IF(H20,I20/H20,0) -> 0.022900763 | X20: =SUM(Y20:AD20) -> 47 | AA20: 34 | AB20: 10 | AC20: 3 | AE20: =SUM(AF20:BD20) -> 81 | AH20: 18 | AJ20: 58 | AM20: 1 | AS20: 1 | AW20: 1 | AY20: 1 | BA20: 1 | BE20: =I20+AE20 -> 84
A21: 10 | B21: Av. Antônio Fidélis, 0, Qd. 67, Lt 31, Oeste/Leste | C21: GYN1R045-2 | D21: =VLOOKUP(C21,Planilha1!$J$2:$L$206,3,) -> 1 | E21: GYN1R045 | F21: 3771 | G21: 1 | H21: =I21+U21 -> 137 | I21: =SUM(J21:T21) -> 3 | L21: 1 | M21: 2 | U21: =X21+AE21 -> 134 | V21: =IF(H21,U21/H21,0) -> 0.97810219 | W21: =IF(H21,I21/H21,0) -> 0.02189781 | X21: =SUM(Y21:AD21) -> 56 | AA21: 41 | AB21: 14 | AC21: 1 | AE21: =SUM(AF21:BD21) -> 78 | AH21: 8 | AJ21: 59 | AT21: 1 | AY21: 2 | AZ21: 6 | BA21: 1 | BC21: 1 | BE21: =I21+AE21 -> 81
A22: 11 | B22: Av. Antônio Fidélis, 0, Qd 155 Lt 01E, Leste/Oeste | C22: GYN1R046-1 | D22: =VLOOKUP(C22,Planilha1!$J$2:$L$206,3,) -> 1 | E22: GYN1R046 | F22: 3920 | G22: 1 | H22: =I22+U22 -> 691 | I22: =SUM(J22:T22) -> 4 | M22: 1 | P22: 2 | S22: 1 | U22: =X22+AE22 -> 687 | V22: =IF(H22,U22/H22,0) -> 0.99421129 | W22: =IF(H22,I22/H22,0) -> 0.005788712 | X22: =SUM(Y22:AD22) -> 1 | AA22: 1 | AE22: =SUM(AF22:BD22) -> 686 | AJ22: 684 | AT22: 1 | AY22: 1 | BE22: =I22+AE22 -> 690
A23: 12 | B23: Av. Antônio Fidélis, 0, Qd 155 Lt 01E, Leste/Oeste | C23: GYN1R046-2 | D23: =VLOOKUP(C23,Planilha1!$J$2:$L$206,3,) -> 1 | E23: GYN1R046 | F23: 4049 | G23: 1 | H23: =I23+U23 -> 596 | I23: =SUM(J23:T23) -> 3 | P23: 1 | T23: 2 | U23: =X23+AE23 -> 593 | V23: =IF(H23,U23/H23,0) -> 0.99496644 | W23: =IF(H23,I23/H23,0) -> 0.005033557 | X23: =SUM(Y23:AD23) -> 3 | AA23: 3 | AE23: =SUM(AF23:BD23) -> 590 | AJ23: 583 | AM23: 3 | AY23: 3 | BC23: 1 | BE23: =I23+AE23 -> 593
A24: 13 | B24: Av. Padre Orlando Morais X Rua Manaus, S/N, Cond. Livre Buritis, Norte/Sul | C24: GYN1R048-1 | D24: =VLOOKUP(C24,Planilha1!$J$2:$L$206,3,) -> 1 | E24: GYN1R048 | F24: 2000 | G24: 1 | H24: =I24+U24 -> 16 | I24: =SUM(J24:T24) -> 0 | U24: =X24+AE24 -> 16 | V24: =IF(H24,U24/H24,0) -> 1 | W24: =IF(H24,I24/H24,0) -> 0 | X24: =SUM(Y24:AD24) -> 0 | AE24: =SUM(AF24:BD24) -> 16 | AJ24: 12 | AW24: 4 | BE24: =I24+AE24 -> 16
A25: 14 | B25: Av. Padre Orlando Morais X Rua Manaus, S/N, Cond. Livre Buritis, Norte/Sul | C25: GYN1R048-2 | D25: =VLOOKUP(C25,Planilha1!$J$2:$L$206,3,) -> 1 | E25: GYN1R048 | F25: 4660 | G25: 1 | H25: =I25+U25 -> 33 | I25: =SUM(J25:T25) -> 2 | P25: 1 | T25: 1 | U25: =X25+AE25 -> 31 | V25: =IF(H25,U25/H25,0) -> 0.93939394 | W25: =IF(H25,I25/H25,0) -> 0.060606061 | X25: =SUM(Y25:AD25) -> 0 | AE25: =SUM(AF25:BD25) -> 31 | AJ25: 15 | AW25: 16 | BE25: =I25+AE25 -> 33
A26: 15 | B26: Av. Pe. Orlando Morais X Rua Manaus, S/N, Cond. Livre Buritis, Sul/Norte | C26: GYN1R049-1 | D26: =VLOOKUP(C26,Planilha1!$J$2:$L$206,3,) -> 1 | E26: GYN1R049 | F26: 1100 | G26: 1 | H26: =I26+U26 -> 26 | I26: =SUM(J26:T26) -> 0 | U26: =X26+AE26 -> 26 | V26: =IF(H26,U26/H26,0) -> 1 | W26: =IF(H26,I26/H26,0) -> 0 | X26: =SUM(Y26:AD26) -> 0 | AE26: =SUM(AF26:BD26) -> 26 | AJ26: 1 | AW26: 25 | BE26: =I26+AE26 -> 26
A27: 16 | B27: Av. Pe. Orlando Morais X Rua Manaus, S/N, Cond. Livre Buritis, Sul/Norte | C27: GYN1R049-2 | D27: =VLOOKUP(C27,Planilha1!$J$2:$L$206,3,) -> 1 | E27: GYN1R049 | F27: 2916 | G27: 1 | H27: =I27+U27 -> 18 | I27: =SUM(J27:T27) -> 0 | U27: =X27+AE27 -> 18 | V27: =IF(H27,U27/H27,0) -> 1 | W27: =IF(H27,I27/H27,0) -> 0 | X27: =SUM(Y27:AD27) -> 0 | AE27: =SUM(AF27:BD27) -> 18 | AW27: 18 | BE27: =I27+AE27 -> 18
A28: 17 | B28: Av. Independência com Al. Luci Rassi de Oliveira, 0, 0, Leste/Oeste | C28: GYN1R052-1 | D28: =VLOOKUP(C28,Planilha1!$J$2:$L$206,3,) -> 1 | E28: GYN1R052 | F28: 8797 | G28: 2 | H28: =I28+U28 -> 400 | I28: =SUM(J28:T28) -> 0 | U28: =X28+AE28 -> 400 | V28: =IF(H28,U28/H28,0) -> 1 | W28: =IF(H28,I28/H28,0) -> 0 | X28: =SUM(Y28:AD28) -> 0 | AE28: =SUM(AF28:BD28) -> 400 | AH28: 2 | AQ28: 1 | AW28: 391 | AY28: 5 | BC28: 1 | BE28: =I28+AE28 -> 400
A29: 18 | B29: Av. Independência com Al. Luci Rassi de Oliveira, 0, 0, Leste/Oeste | C29: GYN1R052-2 | D29: =VLOOKUP(C29,Planilha1!$J$2:$L$206,3,) -> 1 | E29: GYN1R052 | F29: 11263 | G29: 2 | H29: =I29+U29 -> 253 | I29: =SUM(J29:T29) -> 1 | T29: 1 | U29: =X29+AE29 -> 252 | V29: =IF(H29,U29/H29,0) -> 0.99604743 | W29: =IF(H29,I29/H29,0) -> 0.0039525692 | X29: =SUM(Y29:AD29) -> 0 | AE29: =SUM(AF29:BD29) -> 252 | AH29: 1 | AQ29: 5 | AW29: 242 | AY29: 4 | BE29: =I29+AE29 -> 253
A30: 19 | B30: Av. Independência com Al. Luci Rassi de Oliveira , 0, 0, Oeste/Leste | C30: GYN1R053-1 | D30: =VLOOKUP(C30,Planilha1!$J$2:$L$206,3,) -> 1 | E30: GYN1R053 | F30: 12194 | G30: 2 | H30: =I30+U30 -> 1063 | I30: =SUM(J30:T30) -> 10 | L30: 1 | P30: 2 | T30: 7 | U30: =X30+AE30 -> 1053 | V30: =IF(H30,U30/H30,0) -> 0.99059266 | W30: =IF(H30,I30/H30,0) -> 0.0094073377 | X30: =SUM(Y30:AD30) -> 0 | AE30: =SUM(AF30:BD30) -> 1053 | AH30: 1 | AJ30: 621 | AM30: 1 | AO30: 1 | AQ30: 5 | AS30: 1 | AT30: 2 | AW30: 383 | AY30: 2 | AZ30: 35 | BC30: 1 | BE30: =I30+AE30 -> 1063
A31: 20 | B31: Av. Independência com Al. Luci Rassi de Oliveira , 0, 0, Oeste/Leste | C31: GYN1R053-2 | D31: =VLOOKUP(C31,Planilha1!$J$2:$L$206,3,) -> 1 | E31: GYN1R053 | F31: 13468 | G31: 2 | H31: =I31+U31 -> 531 | I31: =SUM(J31:T31) -> 3 | M31: 1 | P31: 2 | U31: =X31+AE31 -> 528 | V31: =IF(H31,U31/H31,0) -> 0.99435028 | W31: =IF(H31,I31/H31,0) -> 0.0056497175 | X31: =SUM(Y31:AD31) -> 0 | AE31: =SUM(AF31:BD31) -> 528 | AH31: 5 | AJ31: 302 | AL31: 2 | AO31: 3 | AQ31: 2 | AW31: 209 | AY31: 3 | BB31: 2 | BE31: =I31+AE31 -> 531
A32: 21 | D32: =VLOOKUP(C32,Planilha1!$J$2:$L$206,3,) -> #N/A | H32: =I32+U32 -> 0 | I32: =SUM(J32:T32) -> 0 | U32: =X32+AE32 -> 0 | V32: =IF(H32,U32/H32,0) -> 0 | W32: =IF(H32,I32/H32,0) -> 0 | X32: =SUM(Y32:AD32) -> 0 | AE32: =SUM(AF32:BD32) -> 0 | BE32: =I32+AE32 -> 0
A33: 22 | D33: =VLOOKUP(C33,Planilha1!$J$2:$L$206,3,) -> #N/A | H33: =I33+U33 -> 0 | I33: =SUM(J33:T33) -> 0 | U33: =X33+AE33 -> 0 | V33: =IF(H33,U33/H33,0) -> 0 | W33: =IF(H33,I33/H33,0) -> 0 | X33: =SUM(Y33:AD33) -> 0 | AE33: =SUM(AF33:BD33) -> 0 | BE33: =I33+AE33 -> 0
A34: 23 | D34: =VLOOKUP(C34,Planilha1!$J$2:$L$206,3,) -> #N/A | H34: =I34+U34 -> 0 | I34: =SUM(J34:T34) -> 0 | U34: =X34+AE34 -> 0 | V34: =IF(H34,U34/H34,0) -> 0 | W34: =IF(H34,I34/H34,0) -> 0 | X34: =SUM(Y34:AD34) -> 0 | AE34: =SUM(AF34:BD34) -> 0 | BE34: =I34+AE34 -> 0
A35: 24 | D35: =VLOOKUP(C35,Planilha1!$J$2:$L$206,3,) -> #N/A | H35: =I35+U35 -> 0 | I35: =SUM(J35:T35) -> 0 | U35: =X35+AE35 -> 0 | V35: =IF(H35,U35/H35,0) -> 0 | W35: =IF(H35,I35/H35,0) -> 0 | X35: =SUM(Y35:AD35) -> 0 | AE35: =SUM(AF35:BD35) -> 0 | BE35: =I35+AE35 -> 0
A36: 25 | D36: =VLOOKUP(C36,Planilha1!$J$2:$L$206,3,) -> #N/A | H36: =I36+U36 -> 0 | I36: =SUM(J36:T36) -> 0 | U36: =X36+AE36 -> 0 | V36: =IF(H36,U36/H36,0) -> 0 | W36: =IF(H36,I36/H36,0) -> 0 | X36: =SUM(Y36:AD36) -> 0 | AE36: =SUM(AF36:BD36) -> 0 | BE36: =I36+AE36 -> 0
A37: 26 | D37: =VLOOKUP(C37,Planilha1!$J$2:$L$206,3,) -> #N/A | H37: =I37+U37 -> 0 | I37: =SUM(J37:T37) -> 0 | U37: =X37+AE37 -> 0 | V37: =IF(H37,U37/H37,0) -> 0 | W37: =IF(H37,I37/H37,0) -> 0 | X37: =SUM(Y37:AD37) -> 0 | AE37: =SUM(AF37:BD37) -> 0 | BE37: =I37+AE37 -> 0
A38: 27 | D38: =VLOOKUP(C38,Planilha1!$J$2:$L$206,3,) -> #N/A | H38: =I38+U38 -> 0 | I38: =SUM(J38:T38) -> 0 | U38: =X38+AE38 -> 0 | V38: =IF(H38,U38/H38,0) -> 0 | W38: =IF(H38,I38/H38,0) -> 0 | X38: =SUM(Y38:AD38) -> 0 | AE38: =SUM(AF38:BD38) -> 0 | BE38: =I38+AE38 -> 0
A39: 28 | D39: =VLOOKUP(C39,Planilha1!$J$2:$L$206,3,) -> #N/A | H39: =I39+U39 -> 0 | I39: =SUM(J39:T39) -> 0 | U39: =X39+AE39 -> 0 | V39: =IF(H39,U39/H39,0) -> 0 | W39: =IF(H39,I39/H39,0) -> 0 | X39: =SUM(Y39:AD39) -> 0 | AE39: =SUM(AF39:BD39) -> 0 | BE39: =I39+AE39 -> 0
A40: 29 | D40: =VLOOKUP(C40,Planilha1!$J$2:$L$206,3,) -> #N/A | H40: =I40+U40 -> 0 | I40: =SUM(J40:T40) -> 0 | U40: =X40+AE40 -> 0 | V40: =IF(H40,U40/H40,0) -> 0 | W40: =IF(H40,I40/H40,0) -> 0 | X40: =SUM(Y40:AD40) -> 0 | AE40: =SUM(AF40:BD40) -> 0 | BE40: =I40+AE40 -> 0
A41: 30 | D41: =VLOOKUP(C41,Planilha1!$J$2:$L$206,3,) -> #N/A | H41: =I41+U41 -> 0 | I41: =SUM(J41:T41) -> 0 | U41: =X41+AE41 -> 0 | V41: =IF(H41,U41/H41,0) -> 0 | W41: =IF(H41,I41/H41,0) -> 0 | X41: =SUM(Y41:AD41) -> 0 | AE41: =SUM(AF41:BD41) -> 0 | BE41: =I41+AE41 -> 0
A42: 31 | D42: =VLOOKUP(C42,Planilha1!$J$2:$L$206,3,) -> #N/A | H42: =I42+U42 -> 0 | I42: =SUM(J42:T42) -> 0 | U42: =X42+AE42 -> 0 | V42: =IF(H42,U42/H42,0) -> 0 | W42: =IF(H42,I42/H42,0) -> 0 | X42: =SUM(Y42:AD42) -> 0 | AE42: =SUM(AF42:BD42) -> 0 | BE42: =I42+AE42 -> 0
...

Sheet ITEM 02
C1: ='RELATÓRIO APROV. DE LEGÍVEIS'!C1 -> MEDIÇÃO DE SERVIÇOS
C2: ='RELATÓRIO APROV. DE LEGÍVEIS'!C2 -> Pregão Eletrônico Nº 90007/2024 - Processo nº 23.13.000003872-9
C3: ='RELATÓRIO APROV. DE LEGÍVEIS'!C3 -> OBRA: Contratação de empresa para para fornecimento de equipamentos novos e sem uso e de sistemas voltados à segurança global das vias sob circunscrição da Secretaria Municipal de Mobilidade | U3: ='RELATÓRIO APROV. DE LEGÍVEIS'!U3 -> Consórcio Anhanguera Segurança | AX3: ='RELATÓRIO APROV. DE LEGÍVEIS'!AX3 -> CONTRATO NÚMERO: 018/2024
U4: ='RELATÓRIO APROV. DE LEGÍVEIS'!U4 -> Rua Itu, S/N, QD 03 LT 1-E, Sl 1001/1002, Torre 2, Edif. B E B Business, Vl Brasília | AD4: ='RELATÓRIO APROV. DE LEGÍVEIS'!AD4 -> MÊS DE REFERÊNCIA: Abril de 2025 | AX4: ='RELATÓRIO APROV. DE LEGÍVEIS'!AX4 -> DATA DA ASSINATURA: 19/12/2024
C5: ='RELATÓRIO APROV. DE LEGÍVEIS'!C5 -> LOCAL: Diversas vias do Município de Goiânia | U5: ='RELATÓRIO APROV. DE LEGÍVEIS'!U5 -> Aparecida de Goiânia - CEP 74.911-810 | AD5: ='RELATÓRIO APROV. DE LEGÍVEIS'!AD5 -> NÚMERO DA MEDIÇÃO: 002 | AX5: ='RELATÓRIO APROV. DE LEGÍVEIS'!AX5 -> PROCESSO SEI MÃE: 23.13.000003872-9
C6: ='RELATÓRIO APROV. DE LEGÍVEIS'!C6 -> PRAZO DE EXECUÇÃO DOS SERVIÇOS: 60 Meses | U6: ='RELATÓRIO APROV. DE LEGÍVEIS'!U6 -> CNPJ: 58.516.417/0001-91 | AD6: ='RELATÓRIO APROV. DE LEGÍVEIS'!AD6 -> CONTRATADA: CONSÓRCIO ANHANGUERA SEGURANÇA | AX6: ='RELATÓRIO APROV. DE LEGÍVEIS'!AX6 -> PROCESSO SEI: 24.13.000008566-8
C7: ='RELATÓRIO APROV. DE LEGÍVEIS'!C7 -> DATA DA ORDEM DE SERVIÇO: 19/12/2024 | U7: ='RELATÓRIO APROV. DE LEGÍVEIS'!U7 -> E-MAIL: comercial@laborengenharia.com
C10: ITEM 02 | J10: IMAGEM REPETIDA (EM DUPLICIDADE) | K10: DIVERGÊNCIA IMAGEM (PAN / ZOOM) | L10: FALTA DE LUMINOSIDADE (IMAGEM ESCURA) | M10: FORA DE FOCO | N10: IMAGEM SEM PANORÂMICA/ZOOM | O10: PLACA REFLETIVA | P10: PROBLEMAS TÉCNICOS | Q10: VEÍCULO FORA DE ENQUADRAMENTO (CAMERA DESALINHADA) | R10: EXCESSO DE LUMINOSIDADE | S10: FORA DO PRAZO | T10: IMAGEM SEM VEÍCULO | AF10: DATA DE AFERICÃO INVÁLIDA/SEM VERIFICAÇÃO | AG10: DIVERGÊNCIA DE CADASTRO | AH10: EQUIPAMENTO EM TESTE | AI10: ERRO NA TARJA (CONFIGURAÇÕES) | AJ10: IMAGEM DE TESTE | AK10: IMAGEM ENCOBERTA (VEGETAÇÃO) | AL10: INTERFERÊNCIA FÍSICA | AM10: MAIS DE UM VEÍCULO NA FAIXA | AN10: MOTO PERMITIDO PARA CIRCULAÇAO NA VIA | AO10: OUTROS | AP10: PEDESTRE OU VEICULO TRACÃO ANIMAL/HUMANA | AQ10: PLACA ENCOBERTA PROPOSITALMENTE (OBSTRUÇÃO INTENCIONAL) | AR10: PLACA ESTRANGEIRA | AS10: PLACA NAO VISUALIZADA | AT10: PLACA ILEGÍVEL | AU10: REFLEXO SOL NA PLACA | AV10: SEMAFORO COM DEFEITO | AW10: SINALIZAÇÃO INSUFICIENTE | AX10: SITUAÇÃO DE DÚVIDA | AY10: VEÍCULO DE EMERGÊNCIA | AZ10: VEÍCULO ENTRE FAIXAS | BA10: VEÍCULO NAO CADASTRADO (SEM CADASTRO) | BB10: VEÍCULO OFICIAL AUTORIZADO | BC10: VEÍCULO SEM PLACA | BD10: VEICULO/MOTO NÃO É INFRATOR
B11: ENDEREÇO | C11: Faixa | D11: ITEM | E11: Equip | F11: Fluxo | G11: Dias Func. | H11: Registros | I11: Ilegíveis | J11: Erro Técnico | U11: Legíveis | V11: % Medido | W11: % Perda | X11: Válidas | Y11: 56732 | Z11: 60503 | AA11: 74550 | AB11: 74630 | AC11: 74710 | AD11: 75870 | AE11: Inválidas | AF11: Invalidação na Análise | BE11: T.Erro
A12: 1 | B12: Av. Laguna, 0, Oposto Congregação Cristã do Brasil, Norte-Sul | C12: GYN2L031-1 | D12: =VLOOKUP(C12,Planilha1!$J$2:$L$206,3,) -> 2 | E12: GYN2L031 | F12: 43995 | G12: 21 | H12: 97 | I12: 3 | S12: 16 | U12: 94 | V12: 0.96907216 | W12: 0.030927835 | X12: 64 | AA12: 105 | AB12: 14 | AC12: 3 | AE12: 30 | AJ12: 10 | AM12: 1 | AQ12: 16 | AS12: 1 | AT12: 3 | AY12: 11 | BA12: 2 | BC12: 10 | BE12: 33
A13: 2 | B13: Av. Laguna, 0, Oposto Congregação Cristã do Brasil, Norte-Sul | C13: GYN2L031-2 | D13: =VLOOKUP(C13,Planilha1!$J$2:$L$206,3,) -> 2 | E13: GYN2L031 | F13: 71217 | G13: 21 | H13: 105 | I13: 11 | L13: 1 | M13: 1 | P13: 2 | R13: 1 | S13: 31 | U13: 94 | V13: 0.8952381 | W13: 0.1047619 | X13: 58 | AA13: 172 | AB13: 39 | AC13: 11 | AE13: 36 | AJ13: 4 | AM13: 10 | AQ13: 29 | AR13: 1 | AT13: 8 | AU13: 1 | AX13: 1 | AY13: 11 | AZ13: 6 | BA13: 4 | BC13: 20 | BE13: 47
A14: 3 | B14: Av. Laguna, 0, Em frente a Congregação Cristã do Brasil, Sul/Norte | C14: GYN2L032-1 | D14: =VLOOKUP(C14,Planilha1!$J$2:$L$206,3,) -> 2 | E14: GYN2L032 | F14: 46375 | G14: 20 | H14: =I14+U14 -> 274 | I14: =SUM(J14:T14) -> 17 | S14: 17 | U14: =X14+AE14 -> 257 | V14: =IF(H14,U14/H14,0) -> 0.9379562 | W14: =IF(H14,I14/H14,0) -> 0.062043796 | X14: =SUM(Y14:AD14) -> 215 | AA14: 184 | AB14: 31 | AE14: =SUM(AF14:BD14) -> 42 | AG14: 1 | AM14: 1 | AQ14: 8 | AT14: 3 | AY14: 5 | AZ14: 1 | BA14: 6 | BC14: 17 | BE14: =I14+AE14 -> 59
A15: 4 | B15: Av. Laguna, 0, Em frente a Congregação Cristã do Brasil, Sul/Norte | C15: GYN2L032-2 | D15: =VLOOKUP(C15,Planilha1!$J$2:$L$206,3,) -> 2 | E15: GYN2L032 | F15: 78826 | G15: 20 | H15: =I15+U15 -> 284 | I15: =SUM(J15:T15) -> 28 | M15: 1 | Q15: 1 | S15: 26 | U15: =X15+AE15 -> 256 | V15: =IF(H15,U15/H15,0) -> 0.90140845 | W15: =IF(H15,I15/H15,0) -> 0.098591549 | X15: =SUM(Y15:AD15) -> 204 | AA15: 186 | AB15: 16 | AC15: 2 | AE15: =SUM(AF15:BD15) -> 52 | AG15: 1 | AM15: 4 | AQ15: 11 | AS15: 1 | AT15: 2 | AY15: 7 | AZ15: 3 | BA15: 4 | BC15: 19 | BE15: =I15+AE15 -> 80
A16: 5 | B16: Av. Antônio Fidelis, S/N, Qd. 107, Lt. 9 B, Leste/Oeste | C16: GYN2L033-1 | D16: =VLOOKUP(C16,Planilha1!$J$2:$L$206,3,) -> 2 | E16: GYN2L033 | F16: 120542 | G16: 20 | H16: =I16+U16 -> 122 | I16: =SUM(J16:T16) -> 8 | S16: 8 | U16: =X16+AE16 -> 114 | V16: =IF(H16,U16/H16,0) -> 0.93442623 | W16: =IF(H16,I16/H16,0) -> 0.06557377 | X16: =SUM(Y16:AD16) -> 70 | AA16: 61 | AB16: 8 | AC16: 1 | AE16: =SUM(AF16:BD16) -> 44 | AG16: 1 | AJ16: 2 | AM16: 3 | AQ16: 13 | AT16: 3 | AY16: 12 | BA16: 3 | BC16: 7 | BE16: =I16+AE16 -> 52
A17: 6 | B17: Av. Antônio Fidelis, S/N, Qd. 107, Lt. 9 B, Leste/Oeste | C17: GYN2L033-2 | D17: =VLOOKUP(C17,Planilha1!$J$2:$L$206,3,) -> 2 | E17: GYN2L033 | F17: 154755 | G17: 20 | H17: =I17+U17 -> 105 | I17: =SUM(J17:T17) -> 34 | L17: 2 | P17: 4 | Q17: 13 | T17: 15 | U17: =X17+AE17 -> 71 | V17: =IF(H17,U17/H17,0) -> 0.67619048 | W17: =IF(H17,I17/H17,0) -> 0.32380952 | X17: =SUM(Y17:AD17) -> 39 | AA17: 31 | AB17: 5 | AC17: 3 | AE17: =SUM(AF17:BD17) -> 32 | AJ17: 2 | AQ17: 8 | AT17: 3 | AY17: 5 | AZ17: 9 | BA17: 1 | BC17: 4 | BE17: =I17+AE17 -> 66
A18: 7 | B18: Av. Antônio Fidelis, S/N, Qd. 82, Lt. 9 B, Oeste/Leste | C18: GYN2L034-1 | D18: =VLOOKUP(C18,Planilha1!$J$2:$L$206,3,) -> 2 | E18: GYN2L034 | F18: 135125 | G18: 20 | H18: =I18+U18 -> 78 | I18: =SUM(J18:T18) -> 3 | S18: 3 | U18: =X18+AE18 -> 75 | V18: =IF(H18,U18/H18,0) -> 0.96153846 | W18: =IF(H18,I18/H18,0) -> 0.038461538 | X18: =SUM(Y18:AD18) -> 33 | AA18: 26 | AB18: 6 | AC18: 1 | AE18: =SUM(AF18:BD18) -> 42 | AI18: 1 | AJ18: 1 | AM18: 2 | AQ18: 14 | AT18: 2 | AY18: 10 | BA18: 5 | BC18: 7 | BE18: =I18+AE18 -> 45
A19: 8 | B19: Av. Antônio Fidelis, S/N, Qd. 82, Lt. 9 B, Oeste/Leste | C19: GYN2L034-2 | D19: =VLOOKUP(C19,Planilha1!$J$2:$L$206,3,) -> 2 | E19: GYN2L034 | F19: 188632 | G19: 20 | H19: =I19+U19 -> 99 | I19: =SUM(J19:T19) -> 11 | L19: 1 | P19: 1 | Q19: 4 | S19: 2 | T19: 3 | U19: =X19+AE19 -> 88 | V19: =IF(H19,U19/H19,0) -> 0.88888889 | W19: =IF(H19,I19/H19,0) -> 0.11111111 | X19: =SUM(Y19:AD19) -> 34 | AA19: 29 | AB19: 5 | AE19: =SUM(AF19:BD19) -> 54 | AM19: 7 | AQ19: 11 | AT19: 2 | AY19: 10 | AZ19: 8 | BA19: 7 | BC19: 9 | BE19: =I19+AE19 -> 65
A20: 9 | B20: AV PROF ALFREDO DE CASTRO, 0, QD AREA LT 4 B, LESTE/OESTE | C20: GYN2L131-1 | D20: =VLOOKUP(C20,Planilha1!$J$2:$L$206,3,) -> 2 | E20: GYN2L131 | F20: 205870 | G20: 30 | H20: =I20+U20 -> 262 | I20: =SUM(J20:T20) -> 9 | O20: 2 | P20: 1 | Q20: 4 | R20: 2 | U20: =X20+AE20 -> 253 | V20: =IF(H20,U20/H20,0) -> 0.96564885 | W20: =IF(H20,I20/H20,0) -> 0.034351145 | X20: =SUM(Y20:AD20) -> 134 | AA20: 97 | AB20: 28 | AC20: 9 | AE20: =SUM(AF20:BD20) -> 119 | AM20: 1 | AN20: 1 | AQ20: 23 | AT20: 3 | AY20: 47 | AZ20: 5 | BA20: 20 | BB20: 1 | BC20: 18 | BE20: =I20+AE20 -> 128
A21: 10 | B21: AV PROF ALFREDO DE CASTRO, 0, QD AREA LT 4 B, LESTE/OESTE | C21: GYN2L131-2 | D21: =VLOOKUP(C21,Planilha1!$J$2:$L$206,3,) -> 2 | E21: GYN2L131 | F21: 69380 | G21: 30 | H21: =I21+U21 -> 80 | I21: =SUM(J21:T21) -> 4 | O21: 1 | Q21: 1 | T21: 2 | U21: =X21+AE21 -> 76 | V21: =IF(H21,U21/H21,0) -> 0.95 | W21: =IF(H21,I21/H21,0) -> 0.05 | X21: =SUM(Y21:AD21) -> 37 | AA21: 25 | AB21: 10 | AC21: 2 | AE21: =SUM(AF21:BD21) -> 39 | AQ21: 3 | AT21: 1 | AY21: 7 | AZ21: 2 | BC21: 26 | BE21: =I21+AE21 -> 43
A22: 11 | D22: =VLOOKUP(C22,Planilha1!$J$2:$L$206,3,) -> #N/A | H22: =I22+U22 -> 0 | I22: =SUM(J22:T22) -> 0 | U22: =X22+AE22 -> 0 | V22: =IF(H22,U22/H22,0) -> 0 | W22: =IF(H22,I22/H22,0) -> 0 | X22: =SUM(Y22:AD22) -> 0 | AE22: =SUM(AF22:BD22) -> 0 | BE22: =I22+AE22 -> 0
A23: 12 | D23: =VLOOKUP(C23,Planilha1!$J$2:$L$206,3,) -> #N/A | H23: =I23+U23 -> 0 | I23: =SUM(J23:T23) -> 0 | U23: =X23+AE23 -> 0 | V23: =IF(H23,U23/H23,0) -> 0 | W23: =IF(H23,I23/H23,0) -> 0 | X23: =SUM(Y23:AD23) -> 0 | AE23: =SUM(AF23:BD23) -> 0 | BE23: =I23+AE23 -> 0
A24: 13 | D24: =VLOOKUP(C24,Planilha1!$J$2:$L$206,3,) -> #N/A | H24: =I24+U24 -> 0 | I24: =SUM(J24:T24) -> 0 | U24: =X24+AE24 -> 0 | V24: =IF(H24,U24/H24,0) -> 0 | W24: =IF(H24,I24/H24,0) -> 0 | X24: =SUM(Y24:AD24) -> 0 | AE24: =SUM(AF24:BD24) -> 0 | BE24: =I24+AE24 -> 0
A25: 14 | D25: =VLOOKUP(C25,Planilha1!$J$2:$L$206,3,) -> #N/A | H25: =I25+U25 -> 0 | I25: =SUM(J25:T25) -> 0 | U25: =X25+AE25 -> 0 | V25: =IF(H25,U25/H25,0) -> 0 | W25: =IF(H25,I25/H25,0) -> 0 | X25: =SUM(Y25:AD25) -> 0 | AE25: =SUM(AF25:BD25) -> 0 | BE25: =I25+AE25 -> 0
A26: 15 | D26: =VLOOKUP(C26,Planilha1!$J$2:$L$206,3,) -> #N/A | H26: =I26+U26 -> 0 | I26: =SUM(J26:T26) -> 0 | U26: =X26+AE26 -> 0 | V26: =IF(H26,U26/H26,0) -> 0 | W26: =IF(H26,I26/H26,0) -> 0 | X26: =SUM(Y26:AD26) -> 0 | AE26: =SUM(AF26:BD26) -> 0 | BE26: =I26+AE26 -> 0
A27: 16 | D27: =VLOOKUP(C27,Planilha1!$J$2:$L$206,3,) -> #N/A | H27: =I27+U27 -> 0 | I27: =SUM(J27:T27) -> 0 | U27: =X27+AE27 -> 0 | V27: =IF(H27,U27/H27,0) -> 0 | W27: =IF(H27,I27/H27,0) -> 0 | X27: =SUM(Y27:AD27) -> 0 | AE27: =SUM(AF27:BD27) -> 0 | BE27: =I27+AE27 -> 0
A28: 17 | D28: =VLOOKUP(C28,Planilha1!$J$2:$L$206,3,) -> #N/A | H28: =I28+U28 -> 0 | I28: =SUM(J28:T28) -> 0 | U28: =X28+AE28 -> 0 | V28: =IF(H28,U28/H28,0) -> 0 | W28: =IF(H28,I28/H28,0) -> 0 | X28: =SUM(Y28:AD28) -> 0 | AE28: =SUM(AF28:BD28) -> 0 | BE28: =I28+AE28 -> 0
A29: 18 | D29: =VLOOKUP(C29,Planilha1!$J$2:$L$206,3,) -> #N/A | H29: =I29+U29 -> 0 | I29: =SUM(J29:T29) -> 0 | U29: =X29+AE29 -> 0 | V29: =IF(H29,U29/H29,0) -> 0 | W29: =IF(H29,I29/H29,0) -> 0 | X29: =SUM(Y29:AD29) -> 0 | AE29: =SUM(AF29:BD29) -> 0 | BE29: =I29+AE29 -> 0
A30: 19 | D30: =VLOOKUP(C30,Planilha1!$J$2:$L$206,3,) -> #N/A | H30: =I30+U30 -> 0 | I30: =SUM(J30:T30) -> 0 | U30: =X30+AE30 -> 0 | V30: =IF(H30,U30/H30,0) -> 0 | W30: =IF(H30,I30/H30,0) -> 0 | X30: =SUM(Y30:AD30) -> 0 | AE30: =SUM(AF30:BD30) -> 0 | BE30: =I30+AE30 -> 0
A31: 20 | D31: =VLOOKUP(C31,Planilha1!$J$2:$L$206,3,) -> #N/A | H31: =I31+U31 -> 0 | I31: =SUM(J31:T31) -> 0 | U31: =X31+AE31 -> 0 | V31: =IF(H31,U31/H31,0) -> 0 | W31: =IF(H31,I31/H31,0) -> 0 | X31: =SUM(Y31:AD31) -> 0 | AE31: =SUM(AF31:BD31) -> 0 | BE31: =I31+AE31 -> 0
A32: 21 | D32: =VLOOKUP(C32,Planilha1!$J$2:$L$206,3,) -> #N/A | H32: =I32+U32 -> 0 | I32: =SUM(J32:T32) -> 0 | U32: =X32+AE32 -> 0 | V32: =IF(H32,U32/H32,0) -> 0 | W32: =IF(H32,I32/H32,0) -> 0 | X32: =SUM(Y32:AD32) -> 0 | AE32: =SUM(AF32:BD32) -> 0 | BE32: =I32+AE32 -> 0
A33: 22 | D33: =VLOOKUP(C33,Planilha1!$J$2:$L$206,3,) -> #N/A | H33: =I33+U33 -> 0 | I33: =SUM(J33:T33) -> 0 | U33: =X33+AE33 -> 0 | V33: =IF(H33,U33/H33,0) -> 0 | W33: =IF(H33,I33/H33,0) -> 0 | X33: =SUM(Y33:AD33) -> 0 | AE33: =SUM(AF33:BD33) -> 0 | BE33: =I33+AE33 -> 0
... A41: 30 | D41: =VLOOKUP(C41,Planilha1!$J$2:$L$206,3,) -> #N/A | H41: =I41+U41 -> 0 | I41: =SUM(J41:T41) -> 0 | U41: =X41+AE41 -> 0 | V41: =IF(H41,U41/H41,0) -> 0 | W41: =IF(H41,I41/H41,0) -> 0 | X41: =SUM(Y41:AD41) -> 0 | AE41: =SUM(AF41:BD41) -> 0 | BE41: =I41+AE41 -> 0
C42: Total | F42: =SUM(F12:F41) -> 1114717 | H42: =SUM(H12:H41) -> 1506 | I42: =SUM(I12:I41) -> 128 | J42: =SUM(J12:J41) -> 0 | K42: =SUM(K12:K41) -> 0 | L42: =SUM(L12:L41) -> 4 | M42: =SUM(M12:M41) -> 2 | N42: =SUM(N12:N41) -> 0 | O42: =SUM(O12:O41) -> 3 | ... U42: =SUM(U12:U41) -> 1378 | V42: =IF(H42,U42/H42,0) -> 0.91500664 | W42: =IF(H42,I42/H42,0) -> 0.08499336 | X42: =SUM(X12:X41) -> 888 | Y42: =SUM(Y12:Y41) -> 0 | Z42: =SUM(Z12:Z41) -> 0 | AA42: =SUM(AA12:AA41) -> 916 | AB42: =SUM(AB12:AB41) -> 162 | AC42: =SUM(AC12:AC41) -> 32 | AD42: =SUM(AD12:AD41) -> 0 | AE42: =SUM(AE12:AE41) -> 490 | ... BE42: =SUM(BE12:BE41) -> 618
C44: DATA DA ELABORAÇÃO DA MEDIÇÃO
C48: ='RELATÓRIO APROV. DE LEGÍVEIS'!C421 -> GOIÂNIA, 01 DE SETEMBRO DE 2024

Sheet ITEM 03
C1: ='RELATÓRIO APROV. DE LEGÍVEIS'!C1 -> MEDIÇÃO DE SERVIÇOS
C2: ='RELATÓRIO APROV. DE LEGÍVEIS'!C2 -> Pregão Eletrônico Nº 90007/2024 - Processo nº 23.13.000003872-9
C3: ='RELATÓRIO APROV. DE LEGÍVEIS'!C3 -> OBRA: Contratação de empresa para para fornecimento de equipamentos novos e sem uso e de sistemas voltados à segurança global das vias sob circunscrição da Secretaria Municipal de Mobilidade | U3: ='RELATÓRIO APROV. DE LEGÍVEIS'!U3 -> Consórcio Anhanguera Segurança | AX3: ='RELATÓRIO APROV. DE LEGÍVEIS'!AX3 -> CONTRATO NÚMERO: 018/2024
U4: ='RELATÓRIO APROV. DE LEGÍVEIS'!U4 -> Rua Itu, S/N, QD 03 LT 1-E, Sl 1001/1002, Torre 2, Edif. B E B Business, Vl Brasília | AD4: ='RELATÓRIO APROV. DE LEGÍVEIS'!AD4 -> MÊS DE REFERÊNCIA: Abril de 2025 | AX4: ='RELATÓRIO APROV. DE LEGÍVEIS'!AX4 -> DATA DA ASSINATURA: 19/12/2024
C5: ='RELATÓRIO APROV. DE LEGÍVEIS'!C5 -> LOCAL: Diversas vias do Município de Goiânia | U5: ='RELATÓRIO APROV. DE LEGÍVEIS'!U5 -> Aparecida de Goiânia - CEP 74.911-810 | AD5: ='RELATÓRIO APROV. DE LEGÍVEIS'!AD5 -> NÚMERO DA MEDIÇÃO: 002 | AX5: ='RELATÓRIO APROV. DE LEGÍVEIS'!AX5 -> PROCESSO SEI MÃE: 23.13.000003872-9
C6: ='RELATÓRIO APROV. DE LEGÍVEIS'!C6 -> PRAZO DE EXECUÇÃO DOS SERVIÇOS: 60 Meses | U6: ='RELATÓRIO APROV. DE LEGÍVEIS'!U6 -> CNPJ: 58.516.417/0001-91 | AD6: ='RELATÓRIO APROV. DE LEGÍVEIS'!AD6 -> CONTRATADA: CONSÓRCIO ANHANGUERA SEGURANÇA | AX6: ='RELATÓRIO APROV. DE LEGÍVEIS'!AX6 -> PROCESSO SEI: 24.13.000008566-8
C7: ='RELATÓRIO APROV. DE LEGÍVEIS'!C7 -> DATA DA ORDEM DE SERVIÇO: 19/12/2024 | U7: ='RELATÓRIO APROV. DE LEGÍVEIS'!U7 -> E-MAIL: comercial@laborengenharia.com
C10: ITEM 03 | J10: IMAGEM REPETIDA (EM DUPLICIDADE) | K10: DIVERGÊNCIA IMAGEM (PAN / ZOOM) | L10: FALTA DE LUMINOSIDADE (IMAGEM ESCURA) | M10: FORA DE FOCO | N10: IMAGEM SEM PANORÂMICA/ZOOM | O10: PLACA REFLETIVA | P10: PROBLEMAS TÉCNICOS | Q10: VEÍCULO FORA DE ENQUADRAMENTO (CAMERA DESALINHADA) | R10: EXCESSO DE LUMINOSIDADE | S10: FORA DO PRAZO | T10: IMAGEM SEM VEÍCULO | AF10: DATA DE AFERICÃO INVÁLIDA/SEM VERIFICAÇÃO | AG10: DIVERGÊNCIA DE CADASTRO | AH10: EQUIPAMENTO EM TESTE | AI10: ERRO NA TARJA (CONFIGURAÇÕES) | AJ10: IMAGEM DE TESTE | AK10: IMAGEM ENCOBERTA (VEGETAÇÃO) | AL10: INTERFERÊNCIA FÍSICA | AM10: MAIS DE UM VEÍCULO NA FAIXA | AN10: MOTO PERMITIDO PARA CIRCULAÇAO NA VIA | AO10: OUTROS | AP10: PEDESTRE OU VEICULO TRACÃO ANIMAL/HUMANA | AQ10: PLACA ENCOBERTA PROPOSITALMENTE (OBSTRUÇÃO INTENCIONAL) | AR10: PLACA ESTRANGEIRA | AS10: PLACA NAO VISUALIZADA | AT10: PLACA ILEGÍVEL | AU10: REFLEXO SOL NA PLACA | AV10: SEMAFORO COM DEFEITO | AW10: SINALIZAÇÃO INSUFICIENTE | AX10: SITUAÇÃO DE DÚVIDA | AY10: VEÍCULO DE EMERGÊNCIA | AZ10: VEÍCULO ENTRE FAIXAS | BA10: VEÍCULO NAO CADASTRADO (SEM CADASTRO) | BB10: VEÍCULO OFICIAL AUTORIZADO | BC10: VEÍCULO SEM PLACA | BD10: VEICULO/MOTO NÃO É INFRATOR
B11: ENDEREÇO | C11: Faixa | D11: ITEM | E11: Equip | F11: Fluxo | G11: Dias Func. | H11: Registros | I11: Ilegíveis | J11: Erro Técnico | U11: Legíveis | V11: % Medido | W11: % Perda | X11: Válidas | Y11: 56732 | Z11: 60503 | AA11: 74550 | AB11: 74630 | AC11: 74710 | AD11: 75870 | AE11: Inválidas | AF11: Invalidação na Análise | BE11: T.Erro
A12: 1 | B12: Av. Hailé Pinheiro x R. Do Golfinho, 0, Qd 38 Lt 28, Oeste-Leste | C12: GYN7M001-1 | D12: =VLOOKUP(C12,Planilha1!$J$2:$L$206,3,) -> 3 | E12: GYN7M001 | F12: 60127 | G12: 21 | H12: 1238 | I12: 147 | K12: 1 | M12: 1 | P12: 19 | Q12: 3 | S12: 60 | T12: 3 | U12: 1091 | V12: 0.8812601 | W12: 0.1187399 | X12: 943 | Z12: 55 | AA12: 414 | AB12: 62 | AC12: 2 | AE12: 148 | AG12: 2 | AJ12: 2 | AK12: 23 | AL12: 2 | AM12: 8 | AP12: 4 | AQ12: 12 | AS12: 4 | AT12: 5 | AV12: 1 | AY12: 22 | AZ12: 1 | BA12: 3 | BC12: 5 | BE12: 295
A13: 2 | B13: Av. Hailé Pinheiro x R. Do Golfinho, 0, Qd 38 Lt 28, Oeste-Leste | C13: GYN7M001-2 | D13: =VLOOKUP(C13,Planilha1!$J$2:$L$206,3,) -> 3 | E13: GYN7M001 | F13: 69337 | G13: 21 | H13: 1914 | I13: 300 | P13: 18 | Q13: 1 | S13: 27 | T13: 1 | U13: 1614 | V13: 0.84326019 | W13: 0.15673981 | X13: 1240 | Z13: 59 | AA13: 197 | AB13: 26 | AE13: 374 | AM13: 1 | AP13: 21 | AQ13: 2 | AR13: 1 | AS13: 2 | AT13: 7 | AY13: 8 | AZ13: 5 | BA13: 3 | BC13: 10 | BD13: 1 | BE13: 674
A14: 3 | B14: Av. Mutirão x Av. T-10 B, 3210, 0, Norte/Sul | C14: GYN7M002-1 | D14: =VLOOKUP(C14,Planilha1!$J$2:$L$206,3,) -> 3 | E14: GYN7M002 | F14: 88650 | G14: 18 | H14: =I14+U14 -> 156 | I14: =SUM(J14:T14) -> 11 | K14: 5 | L14: 1 | M14: 1 | N14: 1 | P14: 1 | Q14: 2 | U14: =X14+AE14 -> 145 | V14: =IF(H14,U14/H14,0) -> 0.92948718 | W14: =IF(H14,I14/H14,0) -> 0.070512821 | X14: =SUM(Y14:AD14) -> 108 | Y14: 29 | Z14: 14 | AA14: 56 | AB14: 8 | AC14: 1 | AE14: =SUM(AF14:BD14) -> 37 | AF14: 9 | AL14: 4 | AM14: 4 | AP14: 1 | AQ14: 2 | AT14: 2 | AU14: 1 | AY14: 11 | BA14: 1 | BC14: 2 | BE14: =I14+AE14 -> 48
A15: 4 | B15: Av. Mutirão x Av. T-10 B, 3210, 0, Norte/Sul | C15: GYN7M002-2 | D15: =VLOOKUP(C15,Planilha1!$J$2:$L$206,3,) -> 3 | E15: GYN7M002 | F15: 105208 | G15: 18 | H15: =I15+U15 -> 194 | I15: =SUM(J15:T15) -> 10 | K15: 1 | P15: 2 | Q15: 4 | T15: 3 | U15: =X15+AE15 -> 184 | V15: =IF(H15,U15/H15,0) -> 0.94845361 | W15: =IF(H15,I15/H15,0) -> 0.051546392 | X15: =SUM(Y15:AD15) -> 134 | Y15: 6 | Z15: 19 | AA15: 95 | AB15: 14 | AE15: =SUM(AF15:BD15) -> 50 | AF15: 7 | AL15: 2 | AM15: 3 | AQ15: 3 | AT15: 5 | AY15: 25 | AZ15: 1 | BA15: 1 | BC15: 3 | BE15: =I15+AE15 -> 60
A16: 5 | B16: Av. Mutirão x Av. T-10 B, 3210, 0, Norte/Sul | C16: GYN7M002-3 | D16: =VLOOKUP(C16,Planilha1!$J$2:$L$206,3,) -> 3 | E16: GYN7M002 | F16: 63414 | G16: 18 | H16: =I16+U16 -> 106 | I16: =SUM(J16:T16) -> 21 | K16: 3 | L16: 1 | M16: 1 | P16: 5 | Q16: 3 | T16: 8 | U16: =X16+AE16 -> 85 | V16: =IF(H16,U16/H16,0) -> 0.80188679 | W16: =IF(H16,I16/H16,0) -> 0.19811321 | X16: =SUM(Y16:AD16) -> 51 | Y16: 2 | Z16: 14 | AA16: 31 | AB16: 4 | AE16: =SUM(AF16:BD16) -> 34 | AF16: 2 | AP16: 3 | AQ16: 1 | AS16: 1 | AY16: 19 | AZ16: 3 | BA16: 1 | BC16: 4 | BE16: =I16+AE16 -> 55
A17: 6 | B17: Av. Mutirão x Av. T 10 B, 1440, 0, Sul/Norte | C17: GYN7M003-1 | D17: =VLOOKUP(C17,Planilha1!$J$2:$L$206,3,) -> 3 | E17: GYN7M003 | F17: 68365 | G17: 18 | H17: =I17+U17 -> 70 | I17: =SUM(J17:T17) -> 3 | P17: 2 | Q17: 1 | U17: =X17+AE17 -> 67 | V17: =IF(H17,U17/H17,0) -> 0.95714286 | W17: =IF(H17,I17/H17,0) -> 0.042857143 | X17: =SUM(Y17:AD17) -> 44 | Y17: 1 | Z17: 32 | AA17: 10 | AB17: 1 | AE17: =SUM(AF17:BD17) -> 23 | AM17: 1 | AT17: 1 | AY17: 17 | BC17: 4 | BE17: =I17+AE17 -> 26
A18: 7 | B18: Av. Mutirão x Av. T 10 B, 1440, 0, Sul/Norte | C18: GYN7M003-2 | D18: =VLOOKUP(C18,Planilha1!$J$2:$L$206,3,) -> 3 | E18: GYN7M003 | F18: 87572 | G18: 18 | H18: =I18+U18 -> 139 | I18: =SUM(J18:T18) -> 14 | M18: 1 | P18: 3 | Q18: 5 | S18: 5 | U18: =X18+AE18 -> 125 | V18: =IF(H18,U18/H18,0) -> 0.89928058 | W18: =IF(H18,I18/H18,0) -> 0.10071942 | X18: =SUM(Y18:AD18) -> 92 | Z18: 55 | AA18: 30 | AB18: 7 | AE18: =SUM(AF18:BD18) -> 33 | AJ18: 1 | AM18: 3 | AQ18: 2 | AS18: 1 | AT18: 5 | AY18: 13 | AZ18: 1 | BA18: 1 | BC18: 6 | BE18: =I18+AE18 -> 47
A19: 8 | B19: Av. Mutirão x Av. T 10 B, 1440, 0, Sul/Norte | C19: GYN7M003-3 | D19: =VLOOKUP(C19,Planilha1!$J$2:$L$206,3,) -> 3 | E19: GYN7M003 | F19: 36564 | G19: 18 | H19: =I19+U19 -> 109 | I19: =SUM(J19:T19) -> 25 | K19: 16 | P19: 2 | S19: 5 | T19: 2 | U19: =X19+AE19 -> 84 | V19: =IF(H19,U19/H19,0) -> 0.7706422 | W19: =IF(H19,I19/H19,0) -> 0.2293578 | X19: =SUM(Y19:AD19) -> 47 | Y19: 3 | Z19: 38 | AA19: 5 | AB19: 1 | AE19: =SUM(AF19:BD19) -> 37 | AG19: 1 | AM19: 3 | AO19: 1 | AP19: 8 | AS19: 1 | AT19: 2 | AY19: 15 | AZ19: 1 | BA19: 1 | BC19: 4 | BE19: =I19+AE19 -> 62
A20: 9 | B20: Av. Padre Orlando de M. X Av. Alexandre de Morais, 0, Prox. Assaí, SUL/NORTE | C20: GYN7M101-1 | D20: =VLOOKUP(C20,Planilha1!$J$2:$L$206,3,) -> 3 | E20: GYN7M101 | F20: 81507 | G20: 27 | H20: =I20+U20 -> 1574 | I20: =SUM(J20:T20) -> 51 | O20: 12 | P20: 5 | Q20: 28 | R20: 6 | U20: =X20+AE20 -> 1523 | V20: =IF(H20,U20/H20,0) -> 0.96759848 | W20: =IF(H20,I20/H20,0) -> 0.032401525 | X20: =SUM(Y20:AD20) -> 100 | Y20: 45 | AA20: 43 | AB20: 9 | AC20: 3 | AE20: =SUM(AF20:BD20) -> 1423 | AG20: 2 | AL20: 3 | AM20: 1 | AO20: 1 | AQ20: 2 | AS20: 4 | AT20: 10 | AW20: 1333 | AX20: 3 | AY20: 18 | AZ20: 29 | BA20: 3 | BB20: 1 | BC20: 11 | BD20: 2 | BE20: =I20+AE20 -> 1474
A21: 10 | B21: Av. Padre Orlando de M. X Av. Alexandre de Morais, 0, Prox. Assaí, SUL/NORTE | C21: GYN7M101-2 | D21: =VLOOKUP(C21,Planilha1!$J$2:$L$206,3,) -> 3 | E21: GYN7M101 | F21: 79432 | G21: 18 | H21: =I21+U21 -> 358 | I21: =SUM(J21:T21) -> 45 | M21: 1 | P21: 36 | Q21: 8 | U21: =X21+AE21 -> 313 | V21: =IF(H21,U21/H21,0) -> 0.87430168 | W21: =IF(H21,I21/H21,0) -> 0.12569832 | X21: =SUM(Y21:AD21) -> 169 | Y21: 169 | AE21: =SUM(AF21:BD21) -> 144 | AM21: 3 | AS21: 4 | AW21: 127 | AX21: 2 | AY21: 3 | AZ21: 1 | BC21: 2 | BD21: 2 | BE21: =I21+AE21 -> 189
A22: 11 | D22: =VLOOKUP(C22,Planilha1!$J$2:$L$206,3,) -> #N/A | H22: =I22+U22 -> 0 | I22: =SUM(J22:T22) -> 0 | U22: =X22+AE22 -> 0 | V22: =IF(H22,U22/H22,0) -> 0 | W22: =IF(H22,I22/H22,0) -> 0 | X22: =SUM(Y22:AD22) -> 0 | AE22: =SUM(AF22:BD22) -> 0 | BE22: =I22+AE22 -> 0
A23: 12 | D23: =VLOOKUP(C23,Planilha1!$J$2:$L$206,3,) -> #N/A | H23: =I23+U23 -> 0 | I23: =SUM(J23:T23) -> 0 | U23: =X23+AE23 -> 0 | V23: =IF(H23,U23/H23,0) -> 0 | W23: =IF(H23,I23/H23,0) -> 0 | X23: =SUM(Y23:AD23) -> 0 | AE23: =SUM(AF23:BD23) -> 0 | BE23: =I23+AE23 -> 0
A24: 13 | D24: =VLOOKUP(C24,Planilha1!$J$2:$L$206,3,) -> #N/A | H24: =I24+U24 -> 0 | I24: =SUM(J24:T24) -> 0 | U24: =X24+AE24 -> 0 | V24: =IF(H24,U24/H24,0) -> 0 | W24: =IF(H24,I24/H24,0) -> 0 | X24: =SUM(Y24:AD24) -> 0 | AE24: =SUM(AF24:BD24) -> 0 | BE24: =I24+AE24 -> 0
A25: 14 | D25: =VLOOKUP(C25,Planilha1!$J$2:$L$206,3,) -> #N/A | H25: =I25+U25 -> 0 | I25: =SUM(J25:T25) -> 0 | U25: =X25+AE25 -> 0 | V25: =IF(H25,U25/H25,0) -> 0 | W25: =IF(H25,I25/H25,0) -> 0 | X25: =SUM(Y25:AD25) -> 0 | AE25: =SUM(AF25:BD25) -> 0 | BE25: =I25+AE25 -> 0
A26: 15 | D26: =VLOOKUP(C26,Planilha1!$J$2:$L$206,3,) -> #N/A | H26: =I26+U26 -> 0 | I26: =SUM(J26:T26) -> 0 | U26: =X26+AE26 -> 0 | V26: =IF(H26,U26/H26,0) -> 0 | W26: =IF(H26,I26/H26,0) -> 0 | X26: =SUM(Y26:AD26) -> 0 | AE26: =SUM(AF26:BD26) -> 0 | BE26: =I26+AE26 -> 0
A27: 16 | D27: =VLOOKUP(C27,Planilha1!$J$2:$L$206,3,) -> #N/A | H27: =I27+U27 -> 0 | I27: =SUM(J27:T27) -> 0 | U27: =X27+AE27 -> 0 | V27: =IF(H27,U27/H27,0) -> 0 | W27: =IF(H27,I27/H27,0) -> 0 | X27: =SUM(Y27:AD27) -> 0 | AE27: =SUM(AF27:BD27) -> 0 | BE27: =I27+AE27 -> 0
A28: 17 | D28: =VLOOKUP(C28,Planilha1!$J$2:$L$206,3,) -> #N/A | H28: =I28+U28 -> 0 | I28: =SUM(J28:T28) -> 0 | U28: =X28+AE28 -> 0 | V28: =IF(H28,U28/H28,0) -> 0 | W28: =IF(H28,I28/H28,0) -> 0 | X28: =SUM(Y28:AD28) -> 0 | AE28: =SUM(AF28:BD28) -> 0 | BE28: =I28+AE28 -> 0
A29: 18 | D29: =VLOOKUP(C29,Planilha1!$J$2:$L$206,3,) -> #N/A | H29: =I29+U29 -> 0 | I29: =SUM(J29:T29) -> 0 | U29: =X29+AE29 -> 0 | V29: =IF(H29,U29/H29,0) -> 0 | W29: =IF(H29,I29/H29,0) -> 0 | X29: =SUM(Y29:AD29) -> 0 | AE29: =SUM(AF29:BD29) -> 0 | BE29: =I29+AE29 -> 0
A30: 19 | D30: =VLOOKUP(C30,Planilha1!$J$2:$L$206,3,) -> #N/A | H30: =I30+U30 -> 0 | I30: =SUM(J30:T30) -> 0 | U30: =X30+AE30 -> 0 | V30: =IF(H30,U30/H30,0) -> 0 | W30: =IF(H30,I30/H30,0) -> 0 | X30: =SUM(Y30:AD30) -> 0 | AE30: =SUM(AF30:BD30) -> 0 | BE30: =I30+AE30 -> 0
A31: 20 | D31: =VLOOKUP(C31,Planilha1!$J$2:$L$206,3,) -> #N/A | H31: =I31+U31 -> 0 | I31: =SUM(J31:T31) -> 0 | U31: =X31+AE31 -> 0 | V31: =IF(H31,U31/H31,0) -> 0 | W31: =IF(H31,I31/H31,0) -> 0 | X31: =SUM(Y31:AD31) -> 0 | AE31: =SUM(AF31:BD31) -> 0 | BE31: =I31+AE31 -> 0
A32: 21 | D32: =VLOOKUP(C32,Planilha1!$J$2:$L$206,3,) -> #N/A | H32: =I32+U32 -> 0 | I32: =SUM(J32:T32) -> 0 | U32: =X32+AE32 -> 0 | V32: =IF(H32,U32/H32,0) -> 0 | W32: =IF(H32,I32/H32,0) -> 0 | X32: =SUM(Y32:AD32) -> 0 | AE32: =SUM(AF32:BD32) -> 0 | BE32: =I32+AE32 -> 0
A33: 22 | D33: =VLOOKUP(C33,Planilha1!$J$2:$L$206,3,) -> #N/A | H33: =I33+U33 -> 0 | I33: =SUM(J33:T33) -> 0 | U33: =X33+AE33 -> 0 | V33: =IF(H33,U33/H33,0) -> 0 | W33: =IF(H33,I33/H33,0) -> 0 | X33: =SUM(Y33:AD33) -> 0 | AE33: =SUM(AF33:BD33) -> 0 | BE33: =I33+AE33 -> 0
... A194: 183 | D194: =VLOOKUP(C194,Planilha1!$J$2:$L$206,3,) -> #N/A | H194: =I194+U194 -> 0 | I194: =SUM(J194:T194) -> 0 | U194: =X194+AE194 -> 0 | V194: =IF(H194,U194/H194,0) -> 0 | W194: =IF(H194,I194/H194,0) -> 0 | X194: =SUM(Y194:AD194) -> 0 | AE194: =SUM(AF194:BD194) -> 0 | BE194: =I194+AE194 -> 0
